Workbook
Name Slicer_COLLECTION: #N/A
Name Slicer_COUNTRY: #N/A
Name Slicer_MODE: #N/A
Name Slicer_REGION: #N/A
Name Slicer_TYPE: #N/A

Sheet Overview
B2: FY2026 MASTER BUDGET MODEL
B4: This workbook plans FY2026 revenue, cost, and margin from the ground up, by country, collection, and channel, starting from actual 2025 performance and letting you adjust the assumptions to plan for the new fiscal year.
B6: Data
B7: Every gray 'Query Data' cell in this workbook was pulled via Power Query from meridian.db / SQL Server on 2026-07-20. It is correct as of that date, not live. Two source facts, fact_boutique_sales (direct/boutique channel) and fact_sell_in (wholesale shipments), are each merged with their supporting dimensions (store or wholesale customer to geography, SKU to collection, date to month/year), then appended into one consolidated actuals table, tagged by channel. That table is grouped down to Month x Channel x Collection x Country, which is the grain the Model tab works at.
B11: Workbook structure:
B12: Inputs | C12: Every editable assumption in one place: units per country, price and cost per SKU, collection mix by country, planned new store openings for 2026, and the Boutique/Wholesale and Retail/Online channel splits. Blue is input, black is formula, green is cross-sheet link.
B15: Model | C15: Takes 2025 actuals and 2026 Inputs assumptions and builds FY2026 at Type x Collection x Country x Month grain: a statistical shape (FORECAST.ETS, floored at zero) blended with your manual overrides, priced and costed per SKU, rolled into budgeted units, revenue, COGS, and margin.
B18: Income Statement | C18: The Model's output consolidated into a full P&L, 2025 Actual vs 2026 Budget, monthly and quarterly, down to net income.
B19: Summary | C19: Budget sliced interactively by Mode, Collection, Type, Region, and Country. Topline or detailed view without touching the Model tab.
B20: Budget Export | C20: The Model's output reshaped to match fact_budget's schema exactly, splitting each row into its four channel_id values (Boutique/Wholesale x Retail/Online) using each Country/Collection's Channel Mix shares. This table is used at the end of the process to update the Database with the Official Budget for 2026

Sheet Summary
B2: =IF(E5='Income Statement'!D8,"","INPUTS CHANGED - REFRESH PIVOT TABLE") | D2: OVERVIEW | N2: REGIONAL SPLIT
E4: Revenue | F4: vs LY | G4: Margin vs LY | I4: Mix LY | J4: Mix TY | O4: Revenue | P4: vs LY | Q4: Margin vs LY | S4: Mix LY | T4: Mix TY
D5: TOPLINE | E5: =_xlfn.XLOOKUP($D5,Pivot!$A:$A,Pivot!H:H) -> 1.0443122e+09 | F5: =IFERROR(_xlfn.XLOOKUP($D5,Pivot!$A:$A,Pivot!M:M,0),0) -> 0.096060053 | G5: =IFERROR(_xlfn.XLOOKUP($D5,Pivot!$A:$A,Pivot!N:N,0),0) -> 71 bpts | I5: =IFERROR(_xlfn.XLOOKUP($D5,Pivot!$A:$A,Pivot!O:O,0),0) -> 1 | J5: =IFERROR(_xlfn.XLOOKUP($D5,Pivot!$A:$A,Pivot!P:P,0),0) -> 1 | N5: =IFERROR(Pivot!B37,"") -> EMEA | O5: =IFERROR(_xlfn.XLOOKUP($N5,Pivot!$B:$B,Pivot!H:H,0),0) -> 4.9486286e+08 | P5: =IFERROR(_xlfn.XLOOKUP($N5,Pivot!$B:$B,Pivot!M:M,0),0) -> 0.091014936 | Q5: =IFERROR(_xlfn.XLOOKUP($N5,Pivot!$B:$B,Pivot!N:N,0),0) -> 55 bpts | S5: =IFERROR(_xlfn.XLOOKUP($N5,Pivot!$B:$B,Pivot!O:O,0),0) -> 0.47605615 | T5: =IFERROR(_xlfn.XLOOKUP($N5,Pivot!$B:$B,Pivot!P:P,0),0) -> 0.47386488
N6: =IFERROR(Pivot!B38,"") -> APAC | O6: =IFERROR(_xlfn.XLOOKUP($N6,Pivot!$B:$B,Pivot!H:H,0),0) -> 3.097853e+08 | P6: =IFERROR(_xlfn.XLOOKUP($N6,Pivot!$B:$B,Pivot!M:M,0),0) -> 0.10007617 | Q6: =IFERROR(_xlfn.XLOOKUP($N6,Pivot!$B:$B,Pivot!N:N,0),0) -> 90 bpts | S6: =IFERROR(_xlfn.XLOOKUP($N6,Pivot!$B:$B,Pivot!O:O,0),0) -> 0.29555755 | T6: =IFERROR(_xlfn.XLOOKUP($N6,Pivot!$B:$B,Pivot!P:P,0),0) -> 0.29664052
N7: =IFERROR(Pivot!B39,"") -> NA | O7: =IFERROR(_xlfn.XLOOKUP($N7,Pivot!$B:$B,Pivot!H:H,0),0) -> 1.6842559e+08 | P7: =IFERROR(_xlfn.XLOOKUP($N7,Pivot!$B:$B,Pivot!M:M,0),0) -> 0.087231977 | Q7: =IFERROR(_xlfn.XLOOKUP($N7,Pivot!$B:$B,Pivot!N:N,0),0) -> 56 bpts | S7: =IFERROR(_xlfn.XLOOKUP($N7,Pivot!$B:$B,Pivot!O:O,0),0) -> 0.16258852 | T7: =IFERROR(_xlfn.XLOOKUP($N7,Pivot!$B:$B,Pivot!P:P,0),0) -> 0.16127897
E8: Revenue | F8: vs LY | G8: Margin vs LY | I8: Mix LY | J8: Mix TY | N8: =IFERROR(Pivot!B40,"") -> LATAM | O8: =IFERROR(_xlfn.XLOOKUP($N8,Pivot!$B:$B,Pivot!H:H,0),0) -> 71238416 | P8: =IFERROR(_xlfn.XLOOKUP($N8,Pivot!$B:$B,Pivot!M:M,0),0) -> 0.13633664 | Q8: =IFERROR(_xlfn.XLOOKUP($N8,Pivot!$B:$B,Pivot!N:N,0),0) -> 143 bpts | S8: =IFERROR(_xlfn.XLOOKUP($N8,Pivot!$B:$B,Pivot!O:O,0),0) -> 0.065797783 | T8: =IFERROR(_xlfn.XLOOKUP($N8,Pivot!$B:$B,Pivot!P:P,0),0) -> 0.068215634
D9: Wholesale | E9: =IFERROR(_xlfn.XLOOKUP($D9,Pivot!$B:$B,Pivot!H:H,0),0) -> 7.7447927e+08 | F9: =IFERROR(_xlfn.XLOOKUP($D9,Pivot!$B:$B,Pivot!M:M,0),0) -> 0.067665178 | G9: =IFERROR(_xlfn.XLOOKUP($D9,Pivot!$B:$B,Pivot!N:N,0),0) -> 54 bpts | I9: =IFERROR(_xlfn.XLOOKUP($D9,Pivot!$B:$B,Pivot!O:O,0),0) -> 0.76134015 | J9: =IFERROR(_xlfn.XLOOKUP($D9,Pivot!$B:$B,Pivot!P:P,0),0) -> 0.74161663
D10: Boutique | E10: =IFERROR(_xlfn.XLOOKUP($D10,Pivot!$B:$B,Pivot!H:H,0),0) -> 2.6983289e+08 | F10: =IFERROR(_xlfn.XLOOKUP($D10,Pivot!$B:$B,Pivot!M:M,0),0) -> 0.18664152 | G10: =IFERROR(_xlfn.XLOOKUP($D10,Pivot!$B:$B,Pivot!N:N,0),0) -> 25 bpts | I10: =IFERROR(_xlfn.XLOOKUP($D10,Pivot!$B:$B,Pivot!O:O,0),0) -> 0.23865985 | J10: =IFERROR(_xlfn.XLOOKUP($D10,Pivot!$B:$B,Pivot!P:P,0),0) -> 0.25838337 | O10: Revenue | P10: vs LY | Q10: Margin vs LY | S10: Mix LY | T10: Mix TY
N11: =IFERROR(Pivot!B46,"") -> United States | O11: =IFERROR(_xlfn.XLOOKUP($N11,Pivot!$B:$B,Pivot!H:H,0),0) -> 92133696 | P11: =IFERROR(_xlfn.XLOOKUP($N11,Pivot!$B:$B,Pivot!M:M,0),0) -> 0.08783294 | Q11: =IFERROR(_xlfn.XLOOKUP($N11,Pivot!$B:$B,Pivot!N:N,0),0) -> 55 bpts | S11: =IFERROR(_xlfn.XLOOKUP($N11,Pivot!$B:$B,Pivot!O:O,0),0) -> 0.088891514 | T11: =IFERROR(_xlfn.XLOOKUP($N11,Pivot!$B:$B,Pivot!P:P,0),0) -> 0.088224287
E12: Revenue | F12: vs LY | G12: Margin vs LY | I12: Mix LY | J12: Mix TY | N12: =IFERROR(Pivot!B47,"") -> Switzerland | O12: =IFERROR(_xlfn.XLOOKUP($N12,Pivot!$B:$B,Pivot!H:H,0),0) -> 79478848 | P12: =IFERROR(_xlfn.XLOOKUP($N12,Pivot!$B:$B,Pivot!M:M,0),0) -> 0.092765755 | Q12: =IFERROR(_xlfn.XLOOKUP($N12,Pivot!$B:$B,Pivot!N:N,0),0) -> 55 bpts | S12: =IFERROR(_xlfn.XLOOKUP($N12,Pivot!$B:$B,Pivot!O:O,0),0) -> 0.076335843 | T12: =IFERROR(_xlfn.XLOOKUP($N12,Pivot!$B:$B,Pivot!P:P,0),0) -> 0.076106409
D13: Retail | E13: =IFERROR(_xlfn.XLOOKUP($D13,Pivot!$B:$B,Pivot!H:H,0),0) -> 7.6467998e+08 | F13: =IFERROR(_xlfn.XLOOKUP($D13,Pivot!$B:$B,Pivot!M:M,0),0) -> 0.10122784 | G13: =IFERROR(_xlfn.XLOOKUP($D13,Pivot!$B:$B,Pivot!N:N,0),0) -> 74 bpts | I13: =IFERROR(_xlfn.XLOOKUP($D13,Pivot!$B:$B,Pivot!O:O,0),0) -> 0.72879696 | J13: =IFERROR(_xlfn.XLOOKUP($D13,Pivot!$B:$B,Pivot!P:P,0),0) -> 0.73223314 | N13: =IFERROR(Pivot!B48,"") -> United Kingdom | O13: =IFERROR(_xlfn.XLOOKUP($N13,Pivot!$B:$B,Pivot!H:H,0),0) -> 79547549 | P13: =IFERROR(_xlfn.XLOOKUP($N13,Pivot!$B:$B,Pivot!M:M,0),0) -> 0.096283286 | Q13: =IFERROR(_xlfn.XLOOKUP($N13,Pivot!$B:$B,Pivot!N:N,0),0) -> 55 bpts | S13: =IFERROR(_xlfn.XLOOKUP($N13,Pivot!$B:$B,Pivot!O:O,0),0) -> 0.076156684 | T13: =IFERROR(_xlfn.XLOOKUP($N13,Pivot!$B:$B,Pivot!P:P,0),0) -> 0.076172195
D14: Online | E14: =IFERROR(_xlfn.XLOOKUP($D14,Pivot!$B:$B,Pivot!H:H,0),0) -> 2.7963219e+08 | F14: =IFERROR(_xlfn.XLOOKUP($D14,Pivot!$B:$B,Pivot!M:M,0),0) -> 0.082172807 | G14: =IFERROR(_xlfn.XLOOKUP($D14,Pivot!$B:$B,Pivot!N:N,0),0) -> 61 bpts | I14: =IFERROR(_xlfn.XLOOKUP($D14,Pivot!$B:$B,Pivot!O:O,0),0) -> 0.27120304 | J14: =IFERROR(_xlfn.XLOOKUP($D14,Pivot!$B:$B,Pivot!P:P,0),0) -> 0.26776686 | N14: =IFERROR(Pivot!B49,"") -> Germany | O14: =IFERROR(_xlfn.XLOOKUP($N14,Pivot!$B:$B,Pivot!H:H,0),0) -> 75904894 | P14: =IFERROR(_xlfn.XLOOKUP($N14,Pivot!$B:$B,Pivot!M:M,0),0) -> 0.096069509 | Q14: =IFERROR(_xlfn.XLOOKUP($N14,Pivot!$B:$B,Pivot!N:N,0),0) -> 59 bpts | S14: =IFERROR(_xlfn.XLOOKUP($N14,Pivot!$B:$B,Pivot!O:O,0),0) -> 0.072683477 | T14: =IFERROR(_xlfn.XLOOKUP($N14,Pivot!$B:$B,Pivot!P:P,0),0) -> 0.072684104
N15: =IFERROR(Pivot!B50,"") -> Japan | O15: =IFERROR(_xlfn.XLOOKUP($N15,Pivot!$B:$B,Pivot!H:H,0),0) -> 74351402 | P15: =IFERROR(_xlfn.XLOOKUP($N15,Pivot!$B:$B,Pivot!M:M,0),0) -> 0.086274869 | Q15: =IFERROR(_xlfn.XLOOKUP($N15,Pivot!$B:$B,Pivot!N:N,0),0) -> 64 bpts | S15: =IFERROR(_xlfn.XLOOKUP($N15,Pivot!$B:$B,Pivot!O:O,0),0) -> 0.071837869 | T15: =IFERROR(_xlfn.XLOOKUP($N15,Pivot!$B:$B,Pivot!P:P,0),0) -> 0.07119653
E16: Revenue | F16: vs LY | G16: Margin vs LY | I16: Mix LY | J16: Mix TY | N16: =IFERROR(Pivot!B51,"") -> France | O16: =IFERROR(_xlfn.XLOOKUP($N16,Pivot!$B:$B,Pivot!H:H,0),0) -> 71167772 | P16: =IFERROR(_xlfn.XLOOKUP($N16,Pivot!$B:$B,Pivot!M:M,0),0) -> 0.086084972 | Q16: =IFERROR(_xlfn.XLOOKUP($N16,Pivot!$B:$B,Pivot!N:N,0),0) -> 54 bpts | S16: =IFERROR(_xlfn.XLOOKUP($N16,Pivot!$B:$B,Pivot!O:O,0),0) -> 0.068773889 | T16: =IFERROR(_xlfn.XLOOKUP($N16,Pivot!$B:$B,Pivot!P:P,0),0) -> 0.068147988
D17: =IFERROR(Pivot!B22,"") -> Atelier | E17: =IFERROR(_xlfn.XLOOKUP($D17,Pivot!$B:$B,Pivot!H:H,0),0) -> 1.8825674e+08 | F17: =IFERROR(_xlfn.XLOOKUP($D17,Pivot!$B:$B,Pivot!M:M,0),0) -> 0.097934948 | G17: =IFERROR(_xlfn.XLOOKUP($D17,Pivot!$B:$B,Pivot!N:N,0),0) -> 67 bpts | I17: =IFERROR(_xlfn.XLOOKUP($D17,Pivot!$B:$B,Pivot!O:O,0),0) -> 0.17996081 | J17: =IFERROR(_xlfn.XLOOKUP($D17,Pivot!$B:$B,Pivot!P:P,0),0) -> 0.18026865 | N17: =IFERROR(Pivot!B52,"") -> China | O17: =IFERROR(_xlfn.XLOOKUP($N17,Pivot!$B:$B,Pivot!H:H,0),0) -> 68853049 | P17: =IFERROR(_xlfn.XLOOKUP($N17,Pivot!$B:$B,Pivot!M:M,0),0) -> 0.12458861 | Q17: =IFERROR(_xlfn.XLOOKUP($N17,Pivot!$B:$B,Pivot!N:N,0),0) -> 151 bpts | S17: =IFERROR(_xlfn.XLOOKUP($N17,Pivot!$B:$B,Pivot!O:O,0),0) -> 0.064258933 | T17: =IFERROR(_xlfn.XLOOKUP($N17,Pivot!$B:$B,Pivot!P:P,0),0) -> 0.065931483
D18: =IFERROR(Pivot!B23,"") -> Grand Complication | E18: =IFERROR(_xlfn.XLOOKUP($D18,Pivot!$B:$B,Pivot!H:H,0),0) -> 1.6983548e+08 | F18: =IFERROR(_xlfn.XLOOKUP($D18,Pivot!$B:$B,Pivot!M:M,0),0) -> 0.095573067 | G18: =IFERROR(_xlfn.XLOOKUP($D18,Pivot!$B:$B,Pivot!N:N,0),0) -> 66 bpts | I18: =IFERROR(_xlfn.XLOOKUP($D18,Pivot!$B:$B,Pivot!O:O,0),0) -> 0.16270133 | J18: =IFERROR(_xlfn.XLOOKUP($D18,Pivot!$B:$B,Pivot!P:P,0),0) -> 0.16262904 | N18: =IFERROR(Pivot!B53,"") -> Mexico | O18: =IFERROR(_xlfn.XLOOKUP($N18,Pivot!$B:$B,Pivot!H:H,0),0) -> 46863360 | P18: =IFERROR(_xlfn.XLOOKUP($N18,Pivot!$B:$B,Pivot!M:M,0),0) -> 0.086703873 | Q18: =IFERROR(_xlfn.XLOOKUP($N18,Pivot!$B:$B,Pivot!N:N,0),0) -> 57 bpts | S18: =IFERROR(_xlfn.XLOOKUP($N18,Pivot!$B:$B,Pivot!O:O,0),0) -> 0.045261217 | T18: =IFERROR(_xlfn.XLOOKUP($N18,Pivot!$B:$B,Pivot!P:P,0),0) -> 0.044874858
D19: =IFERROR(Pivot!B24,"") -> Celeste | E19: =IFERROR(_xlfn.XLOOKUP($D19,Pivot!$B:$B,Pivot!H:H,0),0) -> 1.5011745e+08 | F19: =IFERROR(_xlfn.XLOOKUP($D19,Pivot!$B:$B,Pivot!M:M,0),0) -> 0.096821085 | G19: =IFERROR(_xlfn.XLOOKUP($D19,Pivot!$B:$B,Pivot!N:N,0),0) -> 61 bpts | I19: =IFERROR(_xlfn.XLOOKUP($D19,Pivot!$B:$B,Pivot!O:O,0),0) -> 0.14364794 | J19: =IFERROR(_xlfn.XLOOKUP($D19,Pivot!$B:$B,Pivot!P:P,0),0) -> 0.14374768 | N19: =IFERROR(Pivot!B54,"") -> UAE | O19: =IFERROR(_xlfn.XLOOKUP($N19,Pivot!$B:$B,Pivot!H:H,0),0) -> 45173303 | P19: =IFERROR(_xlfn.XLOOKUP($N19,Pivot!$B:$B,Pivot!M:M,0),0) -> 0.090190389 | Q19: =IFERROR(_xlfn.XLOOKUP($N19,Pivot!$B:$B,Pivot!N:N,0),0) -> 54 bpts | S19: =IFERROR(_xlfn.XLOOKUP($N19,Pivot!$B:$B,Pivot!O:O,0),0) -> 0.04348941 | T19: =IFERROR(_xlfn.XLOOKUP($N19,Pivot!$B:$B,Pivot!P:P,0),0) -> 0.043256514
D20: =IFERROR(Pivot!B25,"") -> Heritage | E20: =IFERROR(_xlfn.XLOOKUP($D20,Pivot!$B:$B,Pivot!H:H,0),0) -> 1.3310787e+08 | F20: =IFERROR(_xlfn.XLOOKUP($D20,Pivot!$B:$B,Pivot!M:M,0),0) -> 0.09493213 | G20: =IFERROR(_xlfn.XLOOKUP($D20,Pivot!$B:$B,Pivot!N:N,0),0) -> 71 bpts | I20: =IFERROR(_xlfn.XLOOKUP($D20,Pivot!$B:$B,Pivot!O:O,0),0) -> 0.12759115 | J20: =IFERROR(_xlfn.XLOOKUP($D20,Pivot!$B:$B,Pivot!P:P,0),0) -> 0.12745985 | N20: =IFERROR(Pivot!B55,"") -> South Korea | O20: =IFERROR(_xlfn.XLOOKUP($N20,Pivot!$B:$B,Pivot!H:H,0),0) -> 43348060 | P20: =IFERROR(_xlfn.XLOOKUP($N20,Pivot!$B:$B,Pivot!M:M,0),0) -> 0.085022881 | Q20: =IFERROR(_xlfn.XLOOKUP($N20,Pivot!$B:$B,Pivot!N:N,0),0) -> 57 bpts | S20: =IFERROR(_xlfn.XLOOKUP($N20,Pivot!$B:$B,Pivot!O:O,0),0) -> 0.041930958 | T20: =IFERROR(_xlfn.XLOOKUP($N20,Pivot!$B:$B,Pivot!P:P,0),0) -> 0.041508719
D21: =IFERROR(Pivot!B26,"") -> Lumina | E21: =IFERROR(_xlfn.XLOOKUP($D21,Pivot!$B:$B,Pivot!H:H,0),0) -> 1.0227366e+08 | F21: =IFERROR(_xlfn.XLOOKUP($D21,Pivot!$B:$B,Pivot!M:M,0),0) -> 0.095326389 | G21: =IFERROR(_xlfn.XLOOKUP($D21,Pivot!$B:$B,Pivot!N:N,0),0) -> 65 bpts | I21: =IFERROR(_xlfn.XLOOKUP($D21,Pivot!$B:$B,Pivot!O:O,0),0) -> 0.097999591 | J21: =IFERROR(_xlfn.XLOOKUP($D21,Pivot!$B:$B,Pivot!P:P,0),0) -> 0.097933993 | N21: =IFERROR(Pivot!B56,"") -> Brazil | O21: =IFERROR(_xlfn.XLOOKUP($N21,Pivot!$B:$B,Pivot!H:H,0),0) -> 39604826 | P21: =IFERROR(_xlfn.XLOOKUP($N21,Pivot!$B:$B,Pivot!M:M,0),0) -> 0.19133061 | Q21: =IFERROR(_xlfn.XLOOKUP($N21,Pivot!$B:$B,Pivot!N:N,0),0) -> 220 bpts | S21: =IFERROR(_xlfn.XLOOKUP($N21,Pivot!$B:$B,Pivot!O:O,0),0) -> 0.034891515 | T21: =IFERROR(_xlfn.XLOOKUP($N21,Pivot!$B:$B,Pivot!P:P,0),0) -> 0.037924318
D22: =IFERROR(Pivot!B27,"") -> Nautique | E22: =IFERROR(_xlfn.XLOOKUP($D22,Pivot!$B:$B,Pivot!H:H,0),0) -> 87971574 | F22: =IFERROR(_xlfn.XLOOKUP($D22,Pivot!$B:$B,Pivot!M:M,0),0) -> 0.093541517 | G22: =IFERROR(_xlfn.XLOOKUP($D22,Pivot!$B:$B,Pivot!N:N,0),0) -> 73 bpts | I22: =IFERROR(_xlfn.XLOOKUP($D22,Pivot!$B:$B,Pivot!O:O,0),0) -> 0.084432782 | J22: =IFERROR(_xlfn.XLOOKUP($D22,Pivot!$B:$B,Pivot!P:P,0),0) -> 0.084238772 | N22: =IFERROR(Pivot!B57,"") -> Hong Kong | O22: =IFERROR(_xlfn.XLOOKUP($N22,Pivot!$B:$B,Pivot!H:H,0),0) -> 37213204 | P22: =IFERROR(_xlfn.XLOOKUP($N22,Pivot!$B:$B,Pivot!M:M,0),0) -> 0.097369051 | Q22: =IFERROR(_xlfn.XLOOKUP($N22,Pivot!$B:$B,Pivot!N:N,0),0) -> 58 bpts | S22: =IFERROR(_xlfn.XLOOKUP($N22,Pivot!$B:$B,Pivot!O:O,0),0) -> 0.03559167 | T22: =IFERROR(_xlfn.XLOOKUP($N22,Pivot!$B:$B,Pivot!P:P,0),0) -> 0.035634177
D23: =IFERROR(Pivot!B28,"") -> Sportivo | E23: =IFERROR(_xlfn.XLOOKUP($D23,Pivot!$B:$B,Pivot!H:H,0),0) -> 86284486 | F23: =IFERROR(_xlfn.XLOOKUP($D23,Pivot!$B:$B,Pivot!M:M,0),0) -> 0.096890948 | G23: =IFERROR(_xlfn.XLOOKUP($D23,Pivot!$B:$B,Pivot!N:N,0),0) -> 88 bpts | I23: =IFERROR(_xlfn.XLOOKUP($D23,Pivot!$B:$B,Pivot!O:O,0),0) -> 0.082560684 | J23: =IFERROR(_xlfn.XLOOKUP($D23,Pivot!$B:$B,Pivot!P:P,0),0) -> 0.082623271 | N23: =IFERROR(Pivot!B58,"") -> Netherlands | O23: =IFERROR(_xlfn.XLOOKUP($N23,Pivot!$B:$B,Pivot!H:H,0),0) -> 35176261 | P23: =IFERROR(_xlfn.XLOOKUP($N23,Pivot!$B:$B,Pivot!M:M,0),0) -> 0.086111064 | Q23: =IFERROR(_xlfn.XLOOKUP($N23,Pivot!$B:$B,Pivot!N:N,0),0) -> 54 bpts | S23: =IFERROR(_xlfn.XLOOKUP($N23,Pivot!$B:$B,Pivot!O:O,0),0) -> 0.033992214 | T23: =IFERROR(_xlfn.XLOOKUP($N23,Pivot!$B:$B,Pivot!P:P,0),0) -> 0.033683665
D24: =IFERROR(Pivot!B29,"") -> Terra | E24: =IFERROR(_xlfn.XLOOKUP($D24,Pivot!$B:$B,Pivot!H:H,0),0) -> 50051302 | F24: =IFERROR(_xlfn.XLOOKUP($D24,Pivot!$B:$B,Pivot!M:M,0),0) -> 0.097987764 | G24: =IFERROR(_xlfn.XLOOKUP($D24,Pivot!$B:$B,Pivot!N:N,0),0) -> 84 bpts | I24: =IFERROR(_xlfn.XLOOKUP($D24,Pivot!$B:$B,Pivot!O:O,0),0) -> 0.047843385 | J24: =IFERROR(_xlfn.XLOOKUP($D24,Pivot!$B:$B,Pivot!P:P,0),0) -> 0.04792753 | N24: =IFERROR(Pivot!B59,"") -> Italy | O24: =IFERROR(_xlfn.XLOOKUP($N24,Pivot!$B:$B,Pivot!H:H,0),0) -> 32110359 | P24: =IFERROR(_xlfn.XLOOKUP($N24,Pivot!$B:$B,Pivot!M:M,0),0) -> 0.092314649 | Q24: =IFERROR(_xlfn.XLOOKUP($N24,Pivot!$B:$B,Pivot!N:N,0),0) -> 51 bpts | S24: =IFERROR(_xlfn.XLOOKUP($N24,Pivot!$B:$B,Pivot!O:O,0),0) -> 0.030853285 | T24: =IFERROR(_xlfn.XLOOKUP($N24,Pivot!$B:$B,Pivot!P:P,0),0) -> 0.030747855
D25: =IFERROR(Pivot!B30,"") -> Meridian Classic | E25: =IFERROR(_xlfn.XLOOKUP($D25,Pivot!$B:$B,Pivot!H:H,0),0) -> 43126677 | F25: =IFERROR(_xlfn.XLOOKUP($D25,Pivot!$B:$B,Pivot!M:M,0),0) -> 0.092692426 | G25: =IFERROR(_xlfn.XLOOKUP($D25,Pivot!$B:$B,Pivot!N:N,0),0) -> 87 bpts | I25: =IFERROR(_xlfn.XLOOKUP($D25,Pivot!$B:$B,Pivot!O:O,0),0) -> 0.041424004 | J25: =IFERROR(_xlfn.XLOOKUP($D25,Pivot!$B:$B,Pivot!P:P,0),0) -> 0.04129673 | N25: =IFERROR(Pivot!B60,"") -> Australia | O25: =IFERROR(_xlfn.XLOOKUP($N25,Pivot!$B:$B,Pivot!H:H,0),0) -> 30718394 | P25: =IFERROR(_xlfn.XLOOKUP($N25,Pivot!$B:$B,Pivot!M:M,0),0) -> 0.094645885 | Q25: =IFERROR(_xlfn.XLOOKUP($N25,Pivot!$B:$B,Pivot!N:N,0),0) -> 56 bpts | S25: =IFERROR(_xlfn.XLOOKUP($N25,Pivot!$B:$B,Pivot!O:O,0),0) -> 0.029452955 | T25: =IFERROR(_xlfn.XLOOKUP($N25,Pivot!$B:$B,Pivot!P:P,0),0) -> 0.029414954
D26: =IFERROR(Pivot!B31,"") -> Aventus | E26: =IFERROR(_xlfn.XLOOKUP($D26,Pivot!$B:$B,Pivot!H:H,0),0) -> 33286916 | F26: =IFERROR(_xlfn.XLOOKUP($D26,Pivot!$B:$B,Pivot!M:M,0),0) -> 0.097305006 | G26: =IFERROR(_xlfn.XLOOKUP($D26,Pivot!$B:$B,Pivot!N:N,0),0) -> 91 bpts | I26: =IFERROR(_xlfn.XLOOKUP($D26,Pivot!$B:$B,Pivot!O:O,0),0) -> 0.031838325 | J26: =IFERROR(_xlfn.XLOOKUP($D26,Pivot!$B:$B,Pivot!P:P,0),0) -> 0.031874488 | N26: =IFERROR(Pivot!B61,"") -> Canada | O26: =IFERROR(_xlfn.XLOOKUP($N26,Pivot!$B:$B,Pivot!H:H,0),0) -> 29428532 | P26: =IFERROR(_xlfn.XLOOKUP($N26,Pivot!$B:$B,Pivot!M:M,0),0) -> 0.086193922 | Q26: =IFERROR(_xlfn.XLOOKUP($N26,Pivot!$B:$B,Pivot!N:N,0),0) -> 58 bpts | S26: =IFERROR(_xlfn.XLOOKUP($N26,Pivot!$B:$B,Pivot!O:O,0),0) -> 0.028435786 | T26: =IFERROR(_xlfn.XLOOKUP($N26,Pivot!$B:$B,Pivot!P:P,0),0) -> 0.028179823
N27: =IFERROR(Pivot!B62,"") -> Saudi Arabia | O27: =IFERROR(_xlfn.XLOOKUP($N27,Pivot!$B:$B,Pivot!H:H,0),0) -> 26604173 | P27: =IFERROR(_xlfn.XLOOKUP($N27,Pivot!$B:$B,Pivot!M:M,0),0) -> 0.09151387 | Q27: =IFERROR(_xlfn.XLOOKUP($N27,Pivot!$B:$B,Pivot!N:N,0),0) -> 46 bpts | S27: =IFERROR(_xlfn.XLOOKUP($N27,Pivot!$B:$B,Pivot!O:O,0),0) -> 0.025581413 | T27: =IFERROR(_xlfn.XLOOKUP($N27,Pivot!$B:$B,Pivot!P:P,0),0) -> 0.025475307
N28: =IFERROR(Pivot!B63,"") -> Singapore | O28: =IFERROR(_xlfn.XLOOKUP($N28,Pivot!$B:$B,Pivot!H:H,0),0) -> 25004398 | P28: =IFERROR(_xlfn.XLOOKUP($N28,Pivot!$B:$B,Pivot!M:M,0),0) -> 0.079140806 | Q28: =IFERROR(_xlfn.XLOOKUP($N28,Pivot!$B:$B,Pivot!N:N,0),0) -> 56 bpts | S28: =IFERROR(_xlfn.XLOOKUP($N28,Pivot!$B:$B,Pivot!O:O,0),0) -> 0.024318809 | T28: =IFERROR(_xlfn.XLOOKUP($N28,Pivot!$B:$B,Pivot!P:P,0),0) -> 0.023943413
N29: =IFERROR(Pivot!B64,"") -> Spain | O29: =IFERROR(_xlfn.XLOOKUP($N29,Pivot!$B:$B,Pivot!H:H,0),0) -> 21095213 | P29: =IFERROR(_xlfn.XLOOKUP($N29,Pivot!$B:$B,Pivot!M:M,0),0) -> 0.081145919 | Q29: =IFERROR(_xlfn.XLOOKUP($N29,Pivot!$B:$B,Pivot!N:N,0),0) -> 65 bpts | S29: =IFERROR(_xlfn.XLOOKUP($N29,Pivot!$B:$B,Pivot!O:O,0),0) -> 0.020478758 | T29: =IFERROR(_xlfn.XLOOKUP($N29,Pivot!$B:$B,Pivot!P:P,0),0) -> 0.020200102
N30: =IFERROR(Pivot!B65,"") -> Peru | O30: =IFERROR(_xlfn.XLOOKUP($N30,Pivot!$B:$B,Pivot!H:H,0),0) -> 11872331 | P30: =IFERROR(_xlfn.XLOOKUP($N30,Pivot!$B:$B,Pivot!M:M,0),0) -> 0.073704896 | Q30: =IFERROR(_xlfn.XLOOKUP($N30,Pivot!$B:$B,Pivot!N:N,0),0) -> 78 bpts | S30: =IFERROR(_xlfn.XLOOKUP($N30,Pivot!$B:$B,Pivot!O:O,0),0) -> 0.011605266 | T30: =IFERROR(_xlfn.XLOOKUP($N30,Pivot!$B:$B,Pivot!P:P,0),0) -> 0.011368565
N31: =IFERROR(Pivot!B66,"") -> Vietnam | O31: =IFERROR(_xlfn.XLOOKUP($N31,Pivot!$B:$B,Pivot!H:H,0),0) -> 12312228 | P31: =IFERROR(_xlfn.XLOOKUP($N31,Pivot!$B:$B,Pivot!M:M,0),0) -> 0.30320566 | Q31: =IFERROR(_xlfn.XLOOKUP($N31,Pivot!$B:$B,Pivot!N:N,0),0) -> 275 bpts | S31: =IFERROR(_xlfn.XLOOKUP($N31,Pivot!$B:$B,Pivot!O:O,0),0) -> 0.0099157991 | T31: =IFERROR(_xlfn.XLOOKUP($N31,Pivot!$B:$B,Pivot!P:P,0),0) -> 0.011789797
N32: =IFERROR(Pivot!B67,"") -> Chile | O32: =IFERROR(_xlfn.XLOOKUP($N32,Pivot!$B:$B,Pivot!H:H,0),0) -> 8954264.8 | P32: =IFERROR(_xlfn.XLOOKUP($N32,Pivot!$B:$B,Pivot!M:M,0),0) -> 0.095070348 | Q32: =IFERROR(_xlfn.XLOOKUP($N32,Pivot!$B:$B,Pivot!N:N,0),0) -> 71 bpts | S32: =IFERROR(_xlfn.XLOOKUP($N32,Pivot!$B:$B,Pivot!O:O,0),0) -> 0.0085820676 | T32: =IFERROR(_xlfn.XLOOKUP($N32,Pivot!$B:$B,Pivot!P:P,0),0) -> 0.0085743183
N33: =IFERROR(Pivot!B68,"") -> Taiwan | O33: =IFERROR(_xlfn.XLOOKUP($N33,Pivot!$B:$B,Pivot!H:H,0),0) -> 8349498.7 | P33: =IFERROR(_xlfn.XLOOKUP($N33,Pivot!$B:$B,Pivot!M:M,0),0) -> 0.078238345 | Q33: =IFERROR(_xlfn.XLOOKUP($N33,Pivot!$B:$B,Pivot!N:N,0),0) -> 71 bpts | S33: =IFERROR(_xlfn.XLOOKUP($N33,Pivot!$B:$B,Pivot!O:O,0),0) -> 0.0081273627 | T33: =IFERROR(_xlfn.XLOOKUP($N33,Pivot!$B:$B,Pivot!P:P,0),0) -> 0.0079952135
N34: =IFERROR(Pivot!B69,"") -> Argentina | O34: =IFERROR(_xlfn.XLOOKUP($N34,Pivot!$B:$B,Pivot!H:H,0),0) -> 7486142.6 | P34: =IFERROR(_xlfn.XLOOKUP($N34,Pivot!$B:$B,Pivot!M:M,0),0) -> 0.091932959 | Q34: =IFERROR(_xlfn.XLOOKUP($N34,Pivot!$B:$B,Pivot!N:N,0),0) -> 63 bpts | S34: =IFERROR(_xlfn.XLOOKUP($N34,Pivot!$B:$B,Pivot!O:O,0),0) -> 0.0071955854 | T34: =IFERROR(_xlfn.XLOOKUP($N34,Pivot!$B:$B,Pivot!P:P,0),0) -> 0.0071684912
N35: =IFERROR(Pivot!B70,"") -> Greece | O35: =IFERROR(_xlfn.XLOOKUP($N35,Pivot!$B:$B,Pivot!H:H,0),0) -> 7250288.3 | P35: =IFERROR(_xlfn.XLOOKUP($N35,Pivot!$B:$B,Pivot!M:M,0),0) -> 0.05655251 | Q35: =IFERROR(_xlfn.XLOOKUP($N35,Pivot!$B:$B,Pivot!N:N,0),0) -> 37 bpts | S35: =IFERROR(_xlfn.XLOOKUP($N35,Pivot!$B:$B,Pivot!O:O,0),0) -> 0.0072022502 | T35: =IFERROR(_xlfn.XLOOKUP($N35,Pivot!$B:$B,Pivot!P:P,0),0) -> 0.0069426447
N36: =IFERROR(Pivot!B71,"") -> Belgium | O36: =IFERROR(_xlfn.XLOOKUP($N36,Pivot!$B:$B,Pivot!H:H,0),0) -> 7101675.1 | P36: =IFERROR(_xlfn.XLOOKUP($N36,Pivot!$B:$B,Pivot!M:M,0),0) -> 0.103428 | Q36: =IFERROR(_xlfn.XLOOKUP($N36,Pivot!$B:$B,Pivot!N:N,0),0) -> 57 bpts | S36: =IFERROR(_xlfn.XLOOKUP($N36,Pivot!$B:$B,Pivot!O:O,0),0) -> 0.0067549294 | T36: =IFERROR(_xlfn.XLOOKUP($N36,Pivot!$B:$B,Pivot!P:P,0),0) -> 0.0068003375
N37: =IFERROR(Pivot!B72,"") -> Portugal | O37: =IFERROR(_xlfn.XLOOKUP($N37,Pivot!$B:$B,Pivot!H:H,0),0) -> 6598666.2 | P37: =IFERROR(_xlfn.XLOOKUP($N37,Pivot!$B:$B,Pivot!M:M,0),0) -> 0.097555628 | Q37: =IFERROR(_xlfn.XLOOKUP($N37,Pivot!$B:$B,Pivot!N:N,0),0) -> 47 bpts | S37: =IFERROR(_xlfn.XLOOKUP($N37,Pivot!$B:$B,Pivot!O:O,0),0) -> 0.0063100621 | T37: =IFERROR(_xlfn.XLOOKUP($N37,Pivot!$B:$B,Pivot!P:P,0),0) -> 0.0063186722
N38: =IFERROR(Pivot!B73,"") -> Thailand | O38: =IFERROR(_xlfn.XLOOKUP($N38,Pivot!$B:$B,Pivot!H:H,0),0) -> 5800820.7 | P38: =IFERROR(_xlfn.XLOOKUP($N38,Pivot!$B:$B,Pivot!M:M,0),0) -> -0.056489799 | Q38: =IFERROR(_xlfn.XLOOKUP($N38,Pivot!$B:$B,Pivot!N:N,0),0) -> 35 bpts | S38: =IFERROR(_xlfn.XLOOKUP($N38,Pivot!$B:$B,Pivot!O:O,0),0) -> 0.00645278 | T38: =IFERROR(_xlfn.XLOOKUP($N38,Pivot!$B:$B,Pivot!P:P,0),0) -> 0.0055546808
... N42: =IFERROR(Pivot!B77,"") -> Colombia | O42: =IFERROR(_xlfn.XLOOKUP($N42,Pivot!$B:$B,Pivot!H:H,0),0) -> 3320851.4 | P42: =IFERROR(_xlfn.XLOOKUP($N42,Pivot!$B:$B,Pivot!M:M,0),0) -> -0.010768989 | Q42: =IFERROR(_xlfn.XLOOKUP($N42,Pivot!$B:$B,Pivot!N:N,0),0) -> 59 bpts | S42: =IFERROR(_xlfn.XLOOKUP($N42,Pivot!$B:$B,Pivot!O:O,0),0) -> 0.0035233495 | T42: =IFERROR(_xlfn.XLOOKUP($N42,Pivot!$B:$B,Pivot!P:P,0),0) -> 0.0031799413

Sheet Income Statement
B2: INCOME STATEMENT
C4: 2025 ACTUALS | D4: 2026 BUDGET | E4: % | G4: JAN | H4: FEB | I4: MAR | J4: APR | K4: MAY | L4: JUN | M4: JUL | N4: AUG | O4: SEP | P4: OCT | Q4: NOV | R4: DEC | T4: Q1 | U4: Q2 | V4: Q3 | W4: Q4
B5: Revenue
B6: Boutique Revenue | C6: =SUMIFS(tbl_Model[Revenue2025],tbl_Model[Type],"Boutique") -> 2.2739209e+08 | D6: =SUM(T6,U6,V6,W6) -> 2.6983289e+08 | E6: =D6/C6-1 -> 0.18664152 | G6: =SUMIFS(Model!CF$7:CF$566,tbl_Model[Type],"Boutique") -> 21111266 | H6: =SUMIFS(Model!CG$7:CG$566,tbl_Model[Type],"Boutique") -> 21277833 | I6: =SUMIFS(Model!CH$7:CH$566,tbl_Model[Type],"Boutique") -> 21673857 | J6: =SUMIFS(Model!CI$7:CI$566,tbl_Model[Type],"Boutique") -> 21642805 | K6: =SUMIFS(Model!CJ$7:CJ$566,tbl_Model[Type],"Boutique") -> 22421323 | L6: =SUMIFS(Model!CK$7:CK$566,tbl_Model[Type],"Boutique") -> 22064843 | M6: =SUMIFS(Model!CL$7:CL$566,tbl_Model[Type],"Boutique") -> 22197469 | N6: =SUMIFS(Model!CM$7:CM$566,tbl_Model[Type],"Boutique") -> 22218509 | ... R6: =SUMIFS(Model!CQ$7:CQ$566,tbl_Model[Type],"Boutique") -> 24717392 | T6: =SUM(G6:I6) -> 64062957 | U6: =SUM(J6:L6) -> 66128971 | V6: =SUM(M6:O6) -> 67467387 | W6: =SUM(P6:R6) -> 72173576
B7: Wholesale Revenue | C7: =SUMIFS(tbl_Model[Revenue2025],tbl_Model[Type],"Wholesale") -> 7.2539527e+08 | D7: =SUM(T7,U7,V7,W7) -> 7.7447927e+08 | E7: =D7/C7-1 -> 0.067665178 | G7: =SUMIFS(Model!CF$7:CF$566,tbl_Model[Type],"Wholesale") -> 61271179 | H7: =SUMIFS(Model!CG$7:CG$566,tbl_Model[Type],"Wholesale") -> 60276319 | I7: =SUMIFS(Model!CH$7:CH$566,tbl_Model[Type],"Wholesale") -> 62023811 | J7: =SUMIFS(Model!CI$7:CI$566,tbl_Model[Type],"Wholesale") -> 61542597 | K7: =SUMIFS(Model!CJ$7:CJ$566,tbl_Model[Type],"Wholesale") -> 63624093 | L7: =SUMIFS(Model!CK$7:CK$566,tbl_Model[Type],"Wholesale") -> 63936474 | M7: =SUMIFS(Model!CL$7:CL$566,tbl_Model[Type],"Wholesale") -> 62250855 | N7: =SUMIFS(Model!CM$7:CM$566,tbl_Model[Type],"Wholesale") -> 63075452 | ... R7: =SUMIFS(Model!CQ$7:CQ$566,tbl_Model[Type],"Wholesale") -> 72355199 | T7: =SUM(G7:I7) -> 1.8357131e+08 | U7: =SUM(J7:L7) -> 1.8910316e+08 | V7: =SUM(M7:O7) -> 1.8965225e+08 | W7: =SUM(P7:R7) -> 2.1215255e+08
B8: Total Net Revenue | C8: =SUM(C6:C7) -> 9.5278736e+08 | D8: =SUM(T8,U8,V8,W8) -> 1.0443122e+09 | E8: =D8/C8-1 -> 0.096060053 | G8: =G6+G7 -> 82382445 | H8: =H6+H7 -> 81554153 | I8: =I6+I7 -> 83697668 | J8: =J6+J7 -> 83185401 | K8: =K6+K7 -> 86045416 | L8: =L6+L7 -> 86001317 | M8: =M6+M7 -> 84448323 | N8: =N6+N7 -> 85293961 | ... R8: =R6+R7 -> 97072592 | T8: =SUM(G8:I8) -> 2.4763427e+08 | U8: =SUM(J8:L8) -> 2.5523213e+08 | V8: =SUM(M8:O8) -> 2.5711964e+08 | W8: =SUM(P8:R8) -> 2.8432612e+08
B10: Cost of Goods Sold
B11: Boutique COGS | C11: =SUMIFS(tbl_Model[COGS2025],tbl_Model[Type],"Boutique") -> 55404604 | D11: =SUM(T11,U11,V11,W11) -> 65078881 | E11: =D11/C11-1 -> 0.17461143 | G11: =SUMIFS(Model!CR$7:CR$566,tbl_Model[Type],"Boutique") -> 5098033.4 | H11: =SUMIFS(Model!CS$7:CS$566,tbl_Model[Type],"Boutique") -> 5137872.9 | I11: =SUMIFS(Model!CT$7:CT$566,tbl_Model[Type],"Boutique") -> 5225728.8 | J11: =SUMIFS(Model!CU$7:CU$566,tbl_Model[Type],"Boutique") -> 5218313.1 | K11: =SUMIFS(Model!CV$7:CV$566,tbl_Model[Type],"Boutique") -> 5408822.3 | L11: =SUMIFS(Model!CW$7:CW$566,tbl_Model[Type],"Boutique") -> 5321719.6 | M11: =SUMIFS(Model!CX$7:CX$566,tbl_Model[Type],"Boutique") -> 5349866.6 | N11: =SUMIFS(Model!CY$7:CY$566,tbl_Model[Type],"Boutique") -> 5354404.3 | ... R11: =SUMIFS(Model!DC$7:DC$566,tbl_Model[Type],"Boutique") -> 5958548.1 | T11: =SUM(G11:I11) -> 15461635 | U11: =SUM(J11:L11) -> 15948855 | V11: =SUM(M11:O11) -> 16265582 | W11: =SUM(P11:R11) -> 17402808
B12: Wholesale COGS | C12: =SUMIFS(tbl_Model[COGS2025],tbl_Model[Type],"Wholesale") -> 2.6689593e+08 | D12: =SUM(T12,U12,V12,W12) -> 2.807715e+08 | E12: =D12/C12-1 -> 0.051988713 | G12: =SUMIFS(Model!CR$7:CR$566,tbl_Model[Type],"Wholesale") -> 22220540 | H12: =SUMIFS(Model!CS$7:CS$566,tbl_Model[Type],"Wholesale") -> 21878046 | I12: =SUMIFS(Model!CT$7:CT$566,tbl_Model[Type],"Wholesale") -> 22562637 | J12: =SUMIFS(Model!CU$7:CU$566,tbl_Model[Type],"Wholesale") -> 22326642 | K12: =SUMIFS(Model!CV$7:CV$566,tbl_Model[Type],"Wholesale") -> 23091755 | L12: =SUMIFS(Model!CW$7:CW$566,tbl_Model[Type],"Wholesale") -> 23220122 | M12: =SUMIFS(Model!CX$7:CX$566,tbl_Model[Type],"Wholesale") -> 22548010 | N12: =SUMIFS(Model!CY$7:CY$566,tbl_Model[Type],"Wholesale") -> 22879122 | ... R12: =SUMIFS(Model!DC$7:DC$566,tbl_Model[Type],"Wholesale") -> 26183585 | T12: =SUM(G12:I12) -> 66661223 | U12: =SUM(J12:L12) -> 68638519 | V12: =SUM(M12:O12) -> 68748643 | W12: =SUM(P12:R12) -> 76723117
B13: Total COGS | C13: =SUM(C11:C12) -> 3.2230053e+08 | D13: =SUM(T13,U13,V13,W13) -> 3.4585038e+08 | E13: =D13/C13-1 -> 0.073067993 | G13: =G11+G12 -> 27318573 | H13: =H11+H12 -> 27015919 | I13: =I11+I12 -> 27788366 | J13: =J11+J12 -> 27544955 | K13: =K11+K12 -> 28500577 | L13: =L11+L12 -> 28541842 | M13: =M11+M12 -> 27897876 | N13: =N11+N12 -> 28233526 | ... R13: =R11+R12 -> 32142133 | T13: =SUM(G13:I13) -> 82122858 | U13: =SUM(J13:L13) -> 84587374 | V13: =SUM(M13:O13) -> 85014226 | W13: =SUM(P13:R13) -> 94125926
B15: Gross Profit
B16: Gross Profit | C16: =C8-C13 -> 6.3048682e+08 | D16: =SUM(G16:R16) -> 6.9846178e+08 | E16: =D16/C16-1 -> 0.10781344 | G16: =G8-G13 -> 55063871 | H16: =H8-H13 -> 54538234 | I16: =I8-I13 -> 55909302 | J16: =J8-J13 -> 55640446 | K16: =K8-K13 -> 57544838 | L16: =L8-L13 -> 57459476 | M16: =M8-M13 -> 56550447 | N16: =N8-N13 -> 57060435 | ... R16: =R8-R13 -> 64930459 | T16: =SUM(G16:I16) -> 1.6551141e+08 | U16: =SUM(J16:L16) -> 1.7064476e+08 | V16: =SUM(M16:O16) -> 1.7210541e+08 | W16: =SUM(P16:R16) -> 1.902002e+08
B17: Gross Margin % | C17: =IF(C8=0,0,C16/C8) -> 0.66172879 | D17: =IF(D8=0,0,D16/D8) -> 0.66882471 | E17: =_xlfn.CONCAT(ROUND((D17-C17)*10000,0),"pp") -> 71pp | G17: =IF(G8=0,0,G16/G8) -> 0.66839327 | H17: =IF(H8=0,0,H16/H8) -> 0.66873644 | I17: =IF(I8=0,0,I16/I8) -> 0.66799115 | J17: =IF(J8=0,0,J16/J8) -> 0.66887272 | K17: =IF(K8=0,0,K16/K8) -> 0.66877286 | L17: =IF(L8=0,0,L16/L8) -> 0.6681232 | M17: =IF(M8=0,0,M16/M8) -> 0.66964558 | N17: =IF(N8=0,0,N16/N8) -> 0.66898564 | ... R17: =IF(R8=0,0,R16/R8) -> 0.6688856 | T17: =IF(T8=0,0,T16/T8) -> 0.66837038 | U17: =IF(U8=0,0,U16/U8) -> 0.6685865 | V17: =IF(V8=0,0,V16/V8) -> 0.66935927 | W17: =IF(W8=0,0,W16/W8) -> 0.66895083
B19: Operating Expenses
B20: Ammortisation & Depreciation | C20: =-C8*0.06 -> -57167241 | D20: =SUM(G20:R20) -> -52215608 | E20: =D20/C20-1 -> -0.086616622 | G20: =-G8*0.05 -> -4119122.2 | H20: =-H8*0.05 -> -4077707.6 | I20: =-I8*0.05 -> -4184883.4 | J20: =-J8*0.05 -> -4159270.1 | K20: =-K8*0.05 -> -4302270.8 | L20: =-L8*0.05 -> -4300065.9 | M20: =-M8*0.05 -> -4222416.2 | N20: =-N8*0.05 -> -4264698 | ... R20: =-R8*0.05 -> -4853629.6 | T20: =SUM(G20:I20) -> -12381713 | U20: =SUM(J20:L20) -> -12761607 | V20: =SUM(M20:O20) -> -12855982 | W20: =SUM(P20:R20) -> -14216306
B21: Marketing | C21: =-C8*0.09 -> -85750862 | D21: =SUM(G21:R21) -> -1.0443122e+08 | E21: =D21/C21-1 -> 0.2178445 | G21: =-G8*0.1 -> -8238244.5 | H21: =-H8*0.1 -> -8155415.3 | I21: =-I8*0.1 -> -8369766.8 | J21: =-J8*0.1 -> -8318540.1 | K21: =-K8*0.1 -> -8604541.6 | L21: =-L8*0.1 -> -8600131.7 | M21: =-M8*0.1 -> -8444832.3 | N21: =-N8*0.1 -> -8529396.1 | ... R21: =-R8*0.1 -> -9707259.2 | T21: =SUM(G21:I21) -> -24763427 | U21: =SUM(J21:L21) -> -25523213 | V21: =SUM(M21:O21) -> -25711964 | W21: =SUM(P21:R21) -> -28432612
B22: General & Administrative | C22: =-C8*0.05 -> -47639368 | D22: =SUM(G22:R22) -> -52215608 | E22: =D22/C22-1 -> 0.096060053 | G22: =-G8*0.05 -> -4119122.2 | H22: =-H8*0.05 -> -4077707.6 | I22: =-I8*0.05 -> -4184883.4 | J22: =-J8*0.05 -> -4159270.1 | K22: =-K8*0.05 -> -4302270.8 | L22: =-L8*0.05 -> -4300065.9 | M22: =-M8*0.05 -> -4222416.2 | N22: =-N8*0.05 -> -4264698 | ... R22: =-R8*0.05 -> -4853629.6 | T22: =SUM(G22:I22) -> -12381713 | U22: =SUM(J22:L22) -> -12761607 | V22: =SUM(M22:O22) -> -12855982 | W22: =SUM(P22:R22) -> -14216306
B23: Salaries & Benefits | C23: =-C8*0.2 -> -1.9055747e+08 | D23: =SUM(G23:R23) -> -2.0886243e+08 | E23: =D23/C23-1 -> 0.096060053 | G23: =-G8*0.2 -> -16476489 | H23: =-H8*0.2 -> -16310831 | I23: =-I8*0.2 -> -16739534 | J23: =-J8*0.2 -> -16637080 | K23: =-K8*0.2 -> -17209083 | L23: =-L8*0.2 -> -17200263 | M23: =-M8*0.2 -> -16889665 | N23: =-N8*0.2 -> -17058792 | ... R23: =-R8*0.2 -> -19414518 | T23: =SUM(G23:I23) -> -49526853 | U23: =SUM(J23:L23) -> -51046427 | V23: =SUM(M23:O23) -> -51423928 | W23: =SUM(P23:R23) -> -56865225
B25: Operating Result
B26: Operating Result | C26: =C16+SUM(C20:C23) -> 2.4937188e+08 | D26: =SUM(G26:R26) -> 2.8073691e+08 | E26: =D26/C26-1 -> 0.12577613 | G26: =G16+SUM(G20:G23) -> 22110894 | H26: =H16+SUM(H20:H23) -> 21916573 | I26: =I16+SUM(I20:I23) -> 22430235 | J26: =J16+SUM(J20:J23) -> 22366285 | K26: =K16+SUM(K20:K23) -> 23126672 | L26: =L16+SUM(L20:L23) -> 23058949 | M26: =M16+SUM(M20:M23) -> 22771118 | N26: =N16+SUM(N20:N23) -> 22942851 | ... R26: =R16+SUM(R20:R23) -> 26101422 | T26: =SUM(G26:I26) -> 66457701 | U26: =SUM(J26:L26) -> 68551906 | V26: =SUM(M26:O26) -> 69257557 | W26: =SUM(P26:R26) -> 76469748
B27: Operating Margin % | C27: =IF(C8=0,0,C26/C8) -> 0.26172879 | D27: =IF(D8=0,0,D26/D8) -> 0.26882471 | E27: =_xlfn.CONCAT(ROUND((D27-C27)*10000,0),"pp") -> 71pp | G27: =IF(G8=0,0,G26/G8) -> 0.26839327 | H27: =IF(H8=0,0,H26/H8) -> 0.26873644 | I27: =IF(I8=0,0,I26/I8) -> 0.26799115 | J27: =IF(J8=0,0,J26/J8) -> 0.26887272 | K27: =IF(K8=0,0,K26/K8) -> 0.26877286 | L27: =IF(L8=0,0,L26/L8) -> 0.2681232 | M27: =IF(M8=0,0,M26/M8) -> 0.26964558 | N27: =IF(N8=0,0,N26/N8) -> 0.26898564 | ... R27: =IF(R8=0,0,R26/R8) -> 0.2688856 | T27: =IF(T8=0,0,T26/T8) -> 0.26837038 | U27: =IF(U8=0,0,U26/U8) -> 0.2685865 | V27: =IF(V8=0,0,V26/V8) -> 0.26935927 | W27: =IF(W8=0,0,W26/W8) -> 0.26895083
B29: Interests & Taxes
B30: Net Interests Expenses | C30: =-C26*0.1 -> -24937188 | D30: =-D26*0.09 -> -25266322 | E30: =D30/C30-1 -> 0.013198514 | G30: =-G26*0.09 -> -1989980.4 | H30: =-H26*0.09 -> -1972491.5 | I30: =-I26*0.09 -> -2018721.1 | J30: =-J26*0.09 -> -2012965.7 | K30: =-K26*0.09 -> -2081400.5 | L30: =-L26*0.09 -> -2075305.4 | M30: =-M26*0.09 -> -2049400.6 | N30: =-N26*0.09 -> -2064856.6 | ... R30: =-R26*0.09 -> -2349128 | T30: =-T26*0.09 -> -5981193.1 | U30: =-U26*0.09 -> -6169671.6 | V30: =-V26*0.09 -> -6233180.1 | W30: =-W26*0.09 -> -6882277.3
B31: Corporate Tax | C31: =-(C26-C30)*0.25 -> -68577268 | D31: =-(D26-D30)*0.25 -> -76500809 | E31: =D31/C31-1 -> 0.1155418 | G31: =-(G26-G30)*0.25 -> -6025218.5 | H31: =-(H26-H30)*0.25 -> -5972266.1 | I31: =-(I26-I30)*0.25 -> -6112238.9 | J31: =-(J26-J30)*0.25 -> -6094812.8 | K31: =-(K26-K30)*0.25 -> -6302018.1 | L31: =-(L26-L30)*0.25 -> -6283563.5 | M31: =-(M26-M30)*0.25 -> -6205129.5 | N31: =-(N26-N30)*0.25 -> -6251926.8 | ... R31: =-(R26-R30)*0.25 -> -7112637.4 | T31: =-(T26-T30)*0.25 -> -18109723 | U31: =-(U26-U30)*0.25 -> -18680394 | V31: =-(V26-V30)*0.25 -> -18872684 | W31: =-(W26-W30)*0.25 -> -20838006
B33: Net Income
B34: =B33 -> Net Income | C34: =C26+C30+C31 -> 1.5585743e+08 | D34: =D26+D30+D31 -> 1.7896978e+08 | E34: =D34/C34-1 -> 0.14829165 | G34: =G26+G30+G31 -> 14095695 | H34: =H26+H30+H31 -> 13971815 | I34: =I26+I30+I31 -> 14299275 | J34: =J26+J30+J31 -> 14258507 | K34: =K26+K30+K31 -> 14743253 | L34: =L26+L30+L31 -> 14700080 | M34: =M26+M30+M31 -> 14516587 | N34: =N26+N30+N31 -> 14626067 | ... R34: =R26+R30+R31 -> 16639656 | T34: =T26+T30+T31 -> 42366784 | U34: =U26+U30+U31 -> 43701840 | V34: =V26+V30+V31 -> 44151693 | W34: =W26+W30+W31 -> 48749464
B35: Net Income Margin % | C35: =IF(C8=0,0,C34/C8) -> 0.16358049 | D35: =IF(D8=0,0,D34/D8) -> 0.17137575 | E35: =_xlfn.CONCAT(ROUND((D35-C35)*10000,0),"pp") -> 78pp | G35: =IF(G8=0,0,G34/G8) -> 0.17110071 | H35: =IF(H8=0,0,H34/H8) -> 0.17131948 | I35: =IF(I8=0,0,I34/I8) -> 0.17084436 | J35: =IF(J8=0,0,J34/J8) -> 0.17140636 | K35: =IF(K8=0,0,K34/K8) -> 0.1713427 | L35: =IF(L8=0,0,L34/L8) -> 0.17092854 | M35: =IF(M8=0,0,M34/M8) -> 0.17189906 | N35: =IF(N8=0,0,N34/N8) -> 0.17147834 | ... R35: =IF(R8=0,0,R34/R8) -> 0.17141457 | T35: =IF(T8=0,0,T34/T8) -> 0.17108611 | U35: =IF(U8=0,0,U34/U8) -> 0.1712239 | V35: =IF(V8=0,0,V34/V8) -> 0.17171653 | W35: =IF(W8=0,0,W34/W8) -> 0.17145616

Sheet Inputs
B2: INPUTS | AN2: SUPPORTING TABLES
B4: Color Convention
B5: Blue | C5: Manual planning input. Safe and expected to edit. | N5: X | O5: X | T5: X | W5: X | X5: X | AC5: X | AG5: X | AK5: X
B6: Black | C6: Calculated cell. Don't type over these. | AD6: X | AE6: X | AH6: X | AI6: X | AL6: X
B7: Green | C7: Formula that pulls from another tab.
B8: Gray Italic | C8: 2025 actual, reference only, not editable. | I8: X | J8: X | K8: X | L8: X | M8: X | S8: X | AB8: X | AF8: X | AJ8: X | AP8: X | AS8: X
A11: 1 | B11: Units per Country | F11: Price per SKU | Q11: Collection Mix | V11: Planned New Stores 2026 | Z11: Channel Mix — Boutique vs Wholesale split & Retail vs Online | AD11: Boutique vs Wholesale | AH11: Boutique: Retail vs Online | AK11: Wholesale: Retail vs Online | AN11: Regional Grouping | AR11: Wholesale Margin by Country
B12: Country | C12: Units2025Actual | D12: Units2026 | F12: SKU | G12: SKU_name | H12: Collection | I12: ListPrice2023 | J12: ListPrice2024 | K12: ListPrice2025 | L12: StandardCost2025 | M12: Units2025Actual | N12: BudgetedPrice2026 | O12: BudgetedCost2026 | Q12: country | R12: collection | S12: Mix2025Actual | T12: Mix2026 | V12: Country | W12: PlannedOpening | X12: ModeShiftAssumption | Z12: Country | AA12: Collection | AB12: BoutiqueShare_2025Actual | AC12: BoutiqueShare_2026 | AD12: BoutiqueShare_2026_Effective | AE12: WhlsShare_2026_Effective | AF12: BoutiqueRetailShare_2025Actual | AG12: BoutiqueRetailShare_2026 | AH12: BoutiqueRetailShare_2026_Effective | AI12: BoutiqueOnlineShare_2026_Effective | AJ12: WholesaleRetailShare_2025Actual | AK12: WholesaleRetailShare_2026 | AL12: WholesaleOnlineShare_2026 | AN12: Country | AO12: geo_id | AP12: Region | AR12: Country | AS12: WholesaleMarginPct
B13: Argentina | C13: 468 | D13: 490 | F13: SKU0001 | G13: Nautique Rose Gold 40mm Salmon | H13: Nautique | I13: 19917.05 | J13: 20773.48 | K13: 21666.74 | L13: 5667.97 | M13: 488 | N13: 22300 | O13: 5800 | Q13: Argentina | R13: Atelier | S13: 0.08547 | T13: 0.085470085 | V13: Thailand | W13: 1 | X13: 0.25 | Z13: Argentina | AA13: Atelier | AB13: 0.65 | AC13: 0.6825 | AD13: =MIN(1,MAX(0,tbl_ChannelMix[[#This Row],[BoutiqueShare_2026]]+IF(IFERROR(_xlfn.XLOOKUP(tbl_ChannelMix[[#This Row],[Country]],tbl_PlannedNewStores2026[Country],tbl_PlannedNewStores2026[PlannedOpening],0),0)=1,IFERROR(_xlfn.XLOOKUP(tbl_ChannelMix[[#This Row],[Country]],tbl_PlannedNewStores2026[Country],tbl_PlannedNewStores2026[ModeShiftAssumption],0),0),0))) -> 0.6825 | AE13: =1-tbl_ChannelMix[[#This Row],[BoutiqueShare_2026_Effective]] -> 0.3175 | AF13: 0 | AG13: 0 | AH13: =MIN(1,MAX(0,tbl_ChannelMix[[#This Row],[BoutiqueRetailShare_2026]]+IF(IFERROR(_xlfn.XLOOKUP(tbl_ChannelMix[[#This Row],[Country]],tbl_PlannedNewStores2026[Country],tbl_PlannedNewStores2026[PlannedOpening],0),0)=1,IFERROR(_xlfn.XLOOKUP(tbl_ChannelMix[[#This Row],[Country]],tbl_PlannedNewStores2026[Country],tbl_PlannedNewStores2026[ModeShiftAssumption],0),0),0))) -> 0 | AI13: =1-tbl_ChannelMix[[#This Row],[BoutiqueRetailShare_2026_Effective]] -> 1 | AJ13: 1 | AK13: 1 | AL13: =1-tbl_ChannelMix[[#This Row],[WholesaleRetailShare_2026]] -> 0 | AN13: Switzerland | AO13: 1 | AP13: EMEA | AR13: Switzerland | AS13: 0.305
B14: Australia | C14: 2055 | D14: 2160 | F14: SKU0002 | G14: Nautique Titanium 42mm Salmon | H14: Nautique | I14: 13070.56 | J14: 13632.6 | K14: 14218.8 | L14: 3572.8 | M14: 545 | N14: 14600 | O14: 3600 | Q14: Argentina | R14: Nautique | S14: 0.047008 | T14: 0.047008547 | V14: Colombia | W14: 1 | X14: 0.25 | Z14: Australia | AA14: Atelier | AB14: 0.255395 | AC14: 0.26816547 | AD14: =MIN(1,MAX(0,tbl_ChannelMix[[#This Row],[BoutiqueShare_2026]]+IF(IFERROR(_xlfn.XLOOKUP(tbl_ChannelMix[[#This Row],[Country]],tbl_PlannedNewStores2026[Country],tbl_PlannedNewStores2026[PlannedOpening],0),0)=1,IFERROR(_xlfn.XLOOKUP(tbl_ChannelMix[[#This Row],[Country]],tbl_PlannedNewStores2026[Country],tbl_PlannedNewStores2026[ModeShiftAssumption],0),0),0))) -> 0.26816547 | AE14: =1-tbl_ChannelMix[[#This Row],[BoutiqueShare_2026_Effective]] -> 0.73183453 | AF14: 0.436619 | AG14: 0.43661972 | AH14: =MIN(1,MAX(0,tbl_ChannelMix[[#This Row],[BoutiqueRetailShare_2026]]+IF(IFERROR(_xlfn.XLOOKUP(tbl_ChannelMix[[#This Row],[Country]],tbl_PlannedNewStores2026[Country],tbl_PlannedNewStores2026[PlannedOpening],0),0)=1,IFERROR(_xlfn.XLOOKUP(tbl_ChannelMix[[#This Row],[Country]],tbl_PlannedNewStores2026[Country],tbl_PlannedNewStores2026[ModeShiftAssumption],0),0),0))) -> 0.43661972 | AI14: =1-tbl_ChannelMix[[#This Row],[BoutiqueRetailShare_2026_Effective]] -> 0.56338028 | AJ14: 0.628019 | AK14: 0.62801932 | AL14: =1-tbl_ChannelMix[[#This Row],[WholesaleRetailShare_2026]] -> 0.37198068 | AN14: Germany | AO14: 2 | AP14: EMEA | AR14: Germany | AS14: 0.35
B15: Austria | C15: 264 | D15: 280 | F15: SKU0003 | G15: Nautique Two-Tone 44mm Black | H15: Nautique | I15: 14315.38 | J15: 14930.94 | K15: 15572.97 | L15: 4045.02 | M15: 544 | N15: 16000 | O15: 4100 | Q15: Argentina | R15: Aventus | S15: 0.081196 | T15: 0.081196581 | V15: Vietnam | W15: 1 | X15: 0.15 | Z15: Argentina | AA15: Aventus | AB15: 0.315789 | AC15: 0.33157895 | AD15: =MIN(1,MAX(0,tbl_ChannelMix[[#This Row],[BoutiqueShare_2026]]+IF(IFERROR(_xlfn.XLOOKUP(tbl_ChannelMix[[#This Row],[Country]],tbl_PlannedNewStores2026[Country],tbl_PlannedNewStores2026[PlannedOpening],0),0)=1,IFERROR(_xlfn.XLOOKUP(tbl_ChannelMix[[#This Row],[Country]],tbl_PlannedNewStores2026[Country],tbl_PlannedNewStores2026[ModeShiftAssumption],0),0),0))) -> 0.33157895 | AE15: =1-tbl_ChannelMix[[#This Row],[BoutiqueShare_2026_Effective]] -> 0.66842105 | AF15: 0 | AG15: 0 | AH15: =MIN(1,MAX(0,tbl_ChannelMix[[#This Row],[BoutiqueRetailShare_2026]]+IF(IFERROR(_xlfn.XLOOKUP(tbl_ChannelMix[[#This Row],[Country]],tbl_PlannedNewStores2026[Country],tbl_PlannedNewStores2026[PlannedOpening],0),0)=1,IFERROR(_xlfn.XLOOKUP(tbl_ChannelMix[[#This Row],[Country]],tbl_PlannedNewStores2026[Country],tbl_PlannedNewStores2026[ModeShiftAssumption],0),0),0))) -> 0 | AI15: =1-tbl_ChannelMix[[#This Row],[BoutiqueRetailShare_2026_Effective]] -> 1 | AJ15: 1 | AK15: 1 | AL15: =1-tbl_ChannelMix[[#This Row],[WholesaleRetailShare_2026]] -> 0 | AN15: United Kingdom | AO15: 3 | AP15: EMEA | AR15: United Kingdom | AS15: 0.337
B16: Belgium | C16: 508 | D16: 530 | F16: SKU0004 | G16: Nautique Titanium 40mm Green | H16: Nautique | I16: 13070.56 | J16: 13632.6 | K16: 14218.8 | L16: 3658.12 | M16: 552 | N16: 14600 | O16: 3700 | Q16: Argentina | R16: Lumina | S16: 0.09188 | T16: 0.091880342 | V16: Brazil | W16: 1 | X16: 0.075 | Z16: Argentina | AA16: Celeste | AB16: 0.40909 | AC16: 0.42954545 | AD16: =MIN(1,MAX(0,tbl_ChannelMix[[#This Row],[BoutiqueShare_2026]]+IF(IFERROR(_xlfn.XLOOKUP(tbl_ChannelMix[[#This Row],[Country]],tbl_PlannedNewStores2026[Country],tbl_PlannedNewStores2026[PlannedOpening],0),0)=1,IFERROR(_xlfn.XLOOKUP(tbl_ChannelMix[[#This Row],[Country]],tbl_PlannedNewStores2026[Country],tbl_PlannedNewStores2026[ModeShiftAssumption],0),0),0))) -> 0.42954545 | AE16: =1-tbl_ChannelMix[[#This Row],[BoutiqueShare_2026_Effective]] -> 0.57045455 | AF16: 0 | AG16: 0 | AH16: =MIN(1,MAX(0,tbl_ChannelMix[[#This Row],[BoutiqueRetailShare_2026]]+IF(IFERROR(_xlfn.XLOOKUP(tbl_ChannelMix[[#This Row],[Country]],tbl_PlannedNewStores2026[Country],tbl_PlannedNewStores2026[PlannedOpening],0),0)=1,IFERROR(_xlfn.XLOOKUP(tbl_ChannelMix[[#This Row],[Country]],tbl_PlannedNewStores2026[Country],tbl_PlannedNewStores2026[ModeShiftAssumption],0),0),0))) -> 0 | AI16: =1-tbl_ChannelMix[[#This Row],[BoutiqueRetailShare_2026_Effective]] -> 1 | AJ16: 1 | AK16: 1 | AL16: =1-tbl_ChannelMix[[#This Row],[WholesaleRetailShare_2026]] -> 0 | AN16: France | AO16: 4 | AP16: EMEA | AR16: France | AS16: 0.318
B17: Brazil | C17: 2709 | D17: 3000 | F17: SKU0005 | G17: Nautique White Gold 42mm Silver | H17: Nautique | I17: 19917.05 | J17: 20773.48 | K17: 21666.74 | L17: 5782.74 | M17: 561 | N17: 22300 | O17: 5900 | Q17: Argentina | R17: Terra | S17: 0.1047 | T17: 0.10470085 | V17: China | W17: 1 | X17: 0.05 | Z17: Austria | AA17: Atelier | AB17: 0 | AC17: 0 | AD17: =MIN(1,MAX(0,tbl_ChannelMix[[#This Row],[BoutiqueShare_2026]]+IF(IFERROR(_xlfn.XLOOKUP(tbl_ChannelMix[[#This Row],[Country]],tbl_PlannedNewStores2026[Country],tbl_PlannedNewStores2026[PlannedOpening],0),0)=1,IFERROR(_xlfn.XLOOKUP(tbl_ChannelMix[[#This Row],[Country]],tbl_PlannedNewStores2026[Country],tbl_PlannedNewStores2026[ModeShiftAssumption],0),0),0))) -> 0 | AE17: =1-tbl_ChannelMix[[#This Row],[BoutiqueShare_2026_Effective]] -> 1 | AF17: 0.843 | AG17: 0.843 | AH17: =MIN(1,MAX(0,tbl_ChannelMix[[#This Row],[BoutiqueRetailShare_2026]]+IF(IFERROR(_xlfn.XLOOKUP(tbl_ChannelMix[[#This Row],[Country]],tbl_PlannedNewStores2026[Country],tbl_PlannedNewStores2026[PlannedOpening],0),0)=1,IFERROR(_xlfn.XLOOKUP(tbl_ChannelMix[[#This Row],[Country]],tbl_PlannedNewStores2026[Country],tbl_PlannedNewStores2026[ModeShiftAssumption],0),0),0))) -> 0.843 | AI17: =1-tbl_ChannelMix[[#This Row],[BoutiqueRetailShare_2026_Effective]] -> 0.157 | AJ17: 0 | AK17: 0 | AL17: =1-tbl_ChannelMix[[#This Row],[WholesaleRetailShare_2026]] -> 1 | AN17: Italy | AO17: 5 | AP17: EMEA | AR17: Italy | AS17: 0.319
B18: Canada | C18: 1988 | D18: 2090 | F18: SKU0006 | G18: Nautique White Gold 40mm Silver | H18: Nautique | I18: 19917.05 | J18: 20773.48 | K18: 21666.74 | L18: 5795.9 | M18: 496 | N18: 22300 | O18: 5900 | Q18: Argentina | R18: Meridian Classic | S18: 0.079059 | T18: 0.079059829 | V18: PlannedOpening: 1 | Z18: Argentina | AA18: Grand Complication | AB18: 0.537313 | AC18: 0.5641791 | AD18: =MIN(1,MAX(0,tbl_ChannelMix[[#This Row],[BoutiqueShare_2026]]+IF(IFERROR(_xlfn.XLOOKUP(tbl_ChannelMix[[#This Row],[Country]],tbl_PlannedNewStores2026[Country],tbl_PlannedNewStores2026[PlannedOpening],0),0)=1,IFERROR(_xlfn.XLOOKUP(tbl_ChannelMix[[#This Row],[Country]],tbl_PlannedNewStores2026[Country],tbl_PlannedNewStores2026[ModeShiftAssumption],0),0),0))) -> 0.5641791 | AE18: =1-tbl_ChannelMix[[#This Row],[BoutiqueShare_2026_Effective]] -> 0.4358209 | AF18: 0 | AG18: 0 | AH18: =MIN(1,MAX(0,tbl_ChannelMix[[#This Row],[BoutiqueRetailShare_2026]]+IF(IFERROR(_xlfn.XLOOKUP(tbl_ChannelMix[[#This Row],[Country]],tbl_PlannedNewStores2026[Country],tbl_PlannedNewStores2026[PlannedOpening],0),0)=1,IFERROR(_xlfn.XLOOKUP(tbl_ChannelMix[[#This Row],[Country]],tbl_PlannedNewStores2026[Country],tbl_PlannedNewStores2026[ModeShiftAssumption],0),0),0))) -> 0 | AI18: =1-tbl_ChannelMix[[#This Row],[BoutiqueRetailShare_2026_Effective]] -> 1 | AJ18: 1 | AK18: 1 | AL18: =1-tbl_ChannelMix[[#This Row],[WholesaleRetailShare_2026]] -> 0 | AN18: Spain | AO18: 6 | AP18: EMEA | AR18: Spain | AS18: 0.336
B19: Chile | C19: 540 | D19: 570 | F19: SKU0007 | G19: Nautique Titanium 38mm Black | H19: Nautique | I19: 13070.56 | J19: 13632.6 | K19: 14218.8 | L19: 3652.62 | M19: 457 | N19: 14600 | O19: 3700 | Q19: Argentina | R19: Celeste | S19: 0.141025 | T19: 0.14102564 | V19: ModeShiftAssumption: assumed pp increase to Boutique channel | Z19: Argentina | AA19: Heritage | AB19: 0.484848 | AC19: 0.50909091 | AD19: =MIN(1,MAX(0,tbl_ChannelMix[[#This Row],[BoutiqueShare_2026]]+IF(IFERROR(_xlfn.XLOOKUP(tbl_ChannelMix[[#This Row],[Country]],tbl_PlannedNewStores2026[Country],tbl_PlannedNewStores2026[PlannedOpening],0),0)=1,IFERROR(_xlfn.XLOOKUP(tbl_ChannelMix[[#This Row],[Country]],tbl_PlannedNewStores2026[Country],tbl_PlannedNewStores2026[ModeShiftAssumption],0),0),0))) -> 0.50909091 | AE19: =1-tbl_ChannelMix[[#This Row],[BoutiqueShare_2026_Effective]] -> 0.49090909 | AF19: 0 | AG19: 0 | AH19: =MIN(1,MAX(0,tbl_ChannelMix[[#This Row],[BoutiqueRetailShare_2026]]+IF(IFERROR(_xlfn.XLOOKUP(tbl_ChannelMix[[#This Row],[Country]],tbl_PlannedNewStores2026[Country],tbl_PlannedNewStores2026[PlannedOpening],0),0)=1,IFERROR(_xlfn.XLOOKUP(tbl_ChannelMix[[#This Row],[Country]],tbl_PlannedNewStores2026[Country],tbl_PlannedNewStores2026[ModeShiftAssumption],0),0),0))) -> 0 | AI19: =1-tbl_ChannelMix[[#This Row],[BoutiqueRetailShare_2026_Effective]] -> 1 | AJ19: 1 | AK19: 1 | AL19: =1-tbl_ChannelMix[[#This Row],[WholesaleRetailShare_2026]] -> 0 | AN19: Netherlands | AO19: 7 | AP19: EMEA | AR19: Netherlands | AS19: 0.332
B20: China | C20: 4710 | D20: 5000 | F20: SKU0008 | G20: Nautique Titanium 44mm White | H20: Nautique | I20: 13070.56 | J20: 13632.6 | K20: 14218.8 | L20: 3737.09 | M20: 495 | N20: 14600 | O20: 3800 | Q20: Argentina | R20: Heritage | S20: 0.070512 | T20: 0.070512821 | Z20: Belgium | AA20: Atelier | AB20: 0 | AC20: 0 | AD20: =MIN(1,MAX(0,tbl_ChannelMix[[#This Row],[BoutiqueShare_2026]]+IF(IFERROR(_xlfn.XLOOKUP(tbl_ChannelMix[[#This Row],[Country]],tbl_PlannedNewStores2026[Country],tbl_PlannedNewStores2026[PlannedOpening],0),0)=1,IFERROR(_xlfn.XLOOKUP(tbl_ChannelMix[[#This Row],[Country]],tbl_PlannedNewStores2026[Country],tbl_PlannedNewStores2026[ModeShiftAssumption],0),0),0))) -> 0 | AE20: =1-tbl_ChannelMix[[#This Row],[BoutiqueShare_2026_Effective]] -> 1 | AF20: 0.843 | AG20: 0.843 | AH20: =MIN(1,MAX(0,tbl_ChannelMix[[#This Row],[BoutiqueRetailShare_2026]]+IF(IFERROR(_xlfn.XLOOKUP(tbl_ChannelMix[[#This Row],[Country]],tbl_PlannedNewStores2026[Country],tbl_PlannedNewStores2026[PlannedOpening],0),0)=1,IFERROR(_xlfn.XLOOKUP(tbl_ChannelMix[[#This Row],[Country]],tbl_PlannedNewStores2026[Country],tbl_PlannedNewStores2026[ModeShiftAssumption],0),0),0))) -> 0.843 | AI20: =1-tbl_ChannelMix[[#This Row],[BoutiqueRetailShare_2026_Effective]] -> 0.157 | AJ20: 1 | AK20: 1 | AL20: =1-tbl_ChannelMix[[#This Row],[WholesaleRetailShare_2026]] -> 0 | AN20: UAE | AO20: 8 | AP20: EMEA | AR20: UAE | AS20: 0.326
B21: Colombia | C21: 280 | D21: 350 | F21: SKU0009 | G21: Nautique White Gold 40mm Black | H21: Nautique | I21: 19917.05 | J21: 20773.48 | K21: 21666.74 | L21: 5466.87 | M21: 559 | N21: 22300 | O21: 5600 | Q21: Argentina | R21: Sportivo | S21: 0.155982 | T21: 0.15598291 | Z21: Argentina | AA21: Lumina | AB21: 0.44186 | AC21: 0.46395349 | AD21: =MIN(1,MAX(0,tbl_ChannelMix[[#This Row],[BoutiqueShare_2026]]+IF(IFERROR(_xlfn.XLOOKUP(tbl_ChannelMix[[#This Row],[Country]],tbl_PlannedNewStores2026[Country],tbl_PlannedNewStores2026[PlannedOpening],0),0)=1,IFERROR(_xlfn.XLOOKUP(tbl_ChannelMix[[#This Row],[Country]],tbl_PlannedNewStores2026[Country],tbl_PlannedNewStores2026[ModeShiftAssumption],0),0),0))) -> 0.46395349 | AE21: =1-tbl_ChannelMix[[#This Row],[BoutiqueShare_2026_Effective]] -> 0.53604651 | AF21: 0 | AG21: 0 | AH21: =MIN(1,MAX(0,tbl_ChannelMix[[#This Row],[BoutiqueRetailShare_2026]]+IF(IFERROR(_xlfn.XLOOKUP(tbl_ChannelMix[[#This Row],[Country]],tbl_PlannedNewStores2026[Country],tbl_PlannedNewStores2026[PlannedOpening],0),0)=1,IFERROR(_xlfn.XLOOKUP(tbl_ChannelMix[[#This Row],[Country]],tbl_PlannedNewStores2026[Country],tbl_PlannedNewStores2026[ModeShiftAssumption],0),0),0))) -> 0 | AI21: =1-tbl_ChannelMix[[#This Row],[BoutiqueRetailShare_2026_Effective]] -> 1 | AJ21: 1 | AK21: 1 | AL21: =1-tbl_ChannelMix[[#This Row],[WholesaleRetailShare_2026]] -> 0 | AN21: Saudi Arabia | AO21: 9 | AP21: EMEA | AR21: Saudi Arabia | AS21: 0.342
B22: Estonia | C22: 248 | D22: 260 | F22: SKU0010 | G22: Nautique Yellow Gold 42mm Black | H22: Nautique | I22: 19917.05 | J22: 20773.48 | K22: 21666.74 | L22: 5412.89 | M22: 494 | N22: 22300 | O22: 5500 | Q22: Argentina | R22: Grand Complication | S22: 0.143162 | T22: 0.14316239 | Z22: Argentina | AA22: Meridian Classic | AB22: 0.378378 | AC22: 0.3972973 | AD22: =MIN(1,MAX(0,tbl_ChannelMix[[#This Row],[BoutiqueShare_2026]]+IF(IFERROR(_xlfn.XLOOKUP(tbl_ChannelMix[[#This Row],[Country]],tbl_PlannedNewStores2026[Country],tbl_PlannedNewStores2026[PlannedOpening],0),0)=1,IFERROR(_xlfn.XLOOKUP(tbl_ChannelMix[[#This Row],[Country]],tbl_PlannedNewStores2026[Country],tbl_PlannedNewStores2026[ModeShiftAssumption],0),0),0))) -> 0.3972973 | AE22: =1-tbl_ChannelMix[[#This Row],[BoutiqueShare_2026_Effective]] -> 0.6027027 | AF22: 0 | AG22: 0 | AH22: =MIN(1,MAX(0,tbl_ChannelMix[[#This Row],[BoutiqueRetailShare_2026]]+IF(IFERROR(_xlfn.XLOOKUP(tbl_ChannelMix[[#This Row],[Country]],tbl_PlannedNewStores2026[Country],tbl_PlannedNewStores2026[PlannedOpening],0),0)=1,IFERROR(_xlfn.XLOOKUP(tbl_ChannelMix[[#This Row],[Country]],tbl_PlannedNewStores2026[Country],tbl_PlannedNewStores2026[ModeShiftAssumption],0),0),0))) -> 0 | AI22: =1-tbl_ChannelMix[[#This Row],[BoutiqueRetailShare_2026_Effective]] -> 1 | AJ22: 1 | AK22: 1 | AL22: =1-tbl_ChannelMix[[#This Row],[WholesaleRetailShare_2026]] -> 0 | AN22: Belgium | AO22: 10 | AP22: EMEA | AR22: Belgium | AS22: 0.312
B23: France | C23: 4904 | D23: 5150 | F23: SKU0011 | G23: Nautique White Gold 42mm Green | H23: Nautique | I23: 19917.05 | J23: 20773.48 | K23: 21666.74 | L23: 5673.38 | M23: 532 | N23: 22300 | O23: 5800 | Q23: Australia | R23: Celeste | S23: 0.1236 | T23: 0.12360097 | Z23: Brazil | AA23: Atelier | AB23: 0.094512 | AC23: 0.099237805 | AD23: =MIN(1,MAX(0,tbl_ChannelMix[[#This Row],[BoutiqueShare_2026]]+IF(IFERROR(_xlfn.XLOOKUP(tbl_ChannelMix[[#This Row],[Country]],tbl_PlannedNewStores2026[Country],tbl_PlannedNewStores2026[PlannedOpening],0),0)=1,IFERROR(_xlfn.XLOOKUP(tbl_ChannelMix[[#This Row],[Country]],tbl_PlannedNewStores2026[Country],tbl_PlannedNewStores2026[ModeShiftAssumption],0),0),0))) -> 0.1742378 | AE23: =1-tbl_ChannelMix[[#This Row],[BoutiqueShare_2026_Effective]] -> 0.8257622 | AF23: 1 | AG23: 1 | AH23: =MIN(1,MAX(0,tbl_ChannelMix[[#This Row],[BoutiqueRetailShare_2026]]+IF(IFERROR(_xlfn.XLOOKUP(tbl_ChannelMix[[#This Row],[Country]],tbl_PlannedNewStores2026[Country],tbl_PlannedNewStores2026[PlannedOpening],0),0)=1,IFERROR(_xlfn.XLOOKUP(tbl_ChannelMix[[#This Row],[Country]],tbl_PlannedNewStores2026[Country],tbl_PlannedNewStores2026[ModeShiftAssumption],0),0),0))) -> 1 | AI23: =1-tbl_ChannelMix[[#This Row],[BoutiqueRetailShare_2026_Effective]] -> 0 | AJ23: 0.703703 | AK23: 0.7037037 | AL23: =1-tbl_ChannelMix[[#This Row],[WholesaleRetailShare_2026]] -> 0.2962963 | AN23: Austria | AO23: 11 | AP23: EMEA | AR23: Austria | AS23: 0.311
B24: Germany | C24: 5124 | D24: 5380 | F24: SKU0012 | G24: Nautique Steel 38mm Black | H24: Nautique | I24: 12448.15 | J24: 12983.42 | K24: 13541.71 | L24: 3412.18 | M24: 504 | N24: 13900 | O24: 3500 | Q24: Australia | R24: Terra | S24: 0.102189 | T24: 0.10218978 | Z24: Argentina | AA24: Nautique | AB24: 0.590909 | AC24: 0.62045455 | AD24: =MIN(1,MAX(0,tbl_ChannelMix[[#This Row],[BoutiqueShare_2026]]+IF(IFERROR(_xlfn.XLOOKUP(tbl_ChannelMix[[#This Row],[Country]],tbl_PlannedNewStores2026[Country],tbl_PlannedNewStores2026[PlannedOpening],0),0)=1,IFERROR(_xlfn.XLOOKUP(tbl_ChannelMix[[#This Row],[Country]],tbl_PlannedNewStores2026[Country],tbl_PlannedNewStores2026[ModeShiftAssumption],0),0),0))) -> 0.62045455 | AE24: =1-tbl_ChannelMix[[#This Row],[BoutiqueShare_2026_Effective]] -> 0.37954545 | AF24: 0 | AG24: 0 | AH24: =MIN(1,MAX(0,tbl_ChannelMix[[#This Row],[BoutiqueRetailShare_2026]]+IF(IFERROR(_xlfn.XLOOKUP(tbl_ChannelMix[[#This Row],[Country]],tbl_PlannedNewStores2026[Country],tbl_PlannedNewStores2026[PlannedOpening],0),0)=1,IFERROR(_xlfn.XLOOKUP(tbl_ChannelMix[[#This Row],[Country]],tbl_PlannedNewStores2026[Country],tbl_PlannedNewStores2026[ModeShiftAssumption],0),0),0))) -> 0 | AI24: =1-tbl_ChannelMix[[#This Row],[BoutiqueRetailShare_2026_Effective]] -> 1 | AJ24: 1 | AK24: 1 | AL24: =1-tbl_ChannelMix[[#This Row],[WholesaleRetailShare_2026]] -> 0 | AN24: Portugal | AO24: 12 | AP24: EMEA | AR24: Portugal | AS24: 0.309
B25: Greece | C25: 521 | D25: 550 | F25: SKU0013 | G25: Heritage Steel 44mm Black | H25: Heritage | I25: 19971.49 | J25: 20798.31 | K25: 21659.36 | L25: 4930.98 | M25: 844 | N25: 22300 | O25: 5000 | Q25: Australia | R25: Sportivo | S25: 0.108029 | T25: 0.1080292 | Z25: Argentina | AA25: Sportivo | AB25: 0.452054 | AC25: 0.47465753 | AD25: =MIN(1,MAX(0,tbl_ChannelMix[[#This Row],[BoutiqueShare_2026]]+IF(IFERROR(_xlfn.XLOOKUP(tbl_ChannelMix[[#This Row],[Country]],tbl_PlannedNewStores2026[Country],tbl_PlannedNewStores2026[PlannedOpening],0),0)=1,IFERROR(_xlfn.XLOOKUP(tbl_ChannelMix[[#This Row],[Country]],tbl_PlannedNewStores2026[Country],tbl_PlannedNewStores2026[ModeShiftAssumption],0),0),0))) -> 0.47465753 | AE25: =1-tbl_ChannelMix[[#This Row],[BoutiqueShare_2026_Effective]] -> 0.52534247 | AF25: 0 | AG25: 0 | AH25: =MIN(1,MAX(0,tbl_ChannelMix[[#This Row],[BoutiqueRetailShare_2026]]+IF(IFERROR(_xlfn.XLOOKUP(tbl_ChannelMix[[#This Row],[Country]],tbl_PlannedNewStores2026[Country],tbl_PlannedNewStores2026[PlannedOpening],0),0)=1,IFERROR(_xlfn.XLOOKUP(tbl_ChannelMix[[#This Row],[Country]],tbl_PlannedNewStores2026[Country],tbl_PlannedNewStores2026[ModeShiftAssumption],0),0),0))) -> 0 | AI25: =1-tbl_ChannelMix[[#This Row],[BoutiqueRetailShare_2026_Effective]] -> 1 | AJ25: 1 | AK25: 1 | AL25: =1-tbl_ChannelMix[[#This Row],[WholesaleRetailShare_2026]] -> 0 | AN25: Estonia | AO25: 13 | AP25: EMEA | AR25: Estonia | AS25: 0.305
B26: Hong Kong | C26: 2613 | D26: 2740 | F26: SKU0014 | G26: Heritage Steel 40mm Salmon | H26: Heritage | I26: 19971.49 | J26: 20798.31 | K26: 21659.36 | L26: 4713.77 | M26: 757 | N26: 22300 | O26: 4800 | Q26: Australia | R26: Aventus | S26: 0.081265 | T26: 0.081265207 | Z26: Canada | AA26: Atelier | AB26: 0.089843 | AC26: 0.094335938 | AD26: =MIN(1,MAX(0,tbl_ChannelMix[[#This Row],[BoutiqueShare_2026]]+IF(IFERROR(_xlfn.XLOOKUP(tbl_ChannelMix[[#This Row],[Country]],tbl_PlannedNewStores2026[Country],tbl_PlannedNewStores2026[PlannedOpening],0),0)=1,IFERROR(_xlfn.XLOOKUP(tbl_ChannelMix[[#This Row],[Country]],tbl_PlannedNewStores2026[Country],tbl_PlannedNewStores2026[ModeShiftAssumption],0),0),0))) -> 0.094335938 | AE26: =1-tbl_ChannelMix[[#This Row],[BoutiqueShare_2026_Effective]] -> 0.90566406 | AF26: 1 | AG26: 1 | AH26: =MIN(1,MAX(0,tbl_ChannelMix[[#This Row],[BoutiqueRetailShare_2026]]+IF(IFERROR(_xlfn.XLOOKUP(tbl_ChannelMix[[#This Row],[Country]],tbl_PlannedNewStores2026[Country],tbl_PlannedNewStores2026[PlannedOpening],0),0)=1,IFERROR(_xlfn.XLOOKUP(tbl_ChannelMix[[#This Row],[Country]],tbl_PlannedNewStores2026[Country],tbl_PlannedNewStores2026[ModeShiftAssumption],0),0),0))) -> 1 | AI26: =1-tbl_ChannelMix[[#This Row],[BoutiqueRetailShare_2026_Effective]] -> 0 | AJ26: 0.579399 | AK26: 0.57939914 | AL26: =1-tbl_ChannelMix[[#This Row],[WholesaleRetailShare_2026]] -> 0.42060086 | AN26: Greece | AO26: 14 | AP26: EMEA | AR26: Greece | AS26: 0.316
B27: Italy | C27: 2123 | D27: 2230 | F27: SKU0015 | G27: Heritage Two-Tone 36mm Blue | H27: Heritage | I27: 22967.22 | J27: 23918.06 | K27: 24908.27 | L27: 5336.29 | M27: 776 | N27: 25700 | O27: 5400 | Q27: Australia | R27: Nautique | S27: 0.082238 | T27: 0.082238443 | Z27: Argentina | AA27: Terra | AB27: 0.55102 | AC27: 0.57857143 | AD27: =MIN(1,MAX(0,tbl_ChannelMix[[#This Row],[BoutiqueShare_2026]]+IF(IFERROR(_xlfn.XLOOKUP(tbl_ChannelMix[[#This Row],[Country]],tbl_PlannedNewStores2026[Country],tbl_PlannedNewStores2026[PlannedOpening],0),0)=1,IFERROR(_xlfn.XLOOKUP(tbl_ChannelMix[[#This Row],[Country]],tbl_PlannedNewStores2026[Country],tbl_PlannedNewStores2026[ModeShiftAssumption],0),0),0))) -> 0.57857143 | AE27: =1-tbl_ChannelMix[[#This Row],[BoutiqueShare_2026_Effective]] -> 0.42142857 | AF27: 0 | AG27: 0 | AH27: =MIN(1,MAX(0,tbl_ChannelMix[[#This Row],[BoutiqueRetailShare_2026]]+IF(IFERROR(_xlfn.XLOOKUP(tbl_ChannelMix[[#This Row],[Country]],tbl_PlannedNewStores2026[Country],tbl_PlannedNewStores2026[PlannedOpening],0),0)=1,IFERROR(_xlfn.XLOOKUP(tbl_ChannelMix[[#This Row],[Country]],tbl_PlannedNewStores2026[Country],tbl_PlannedNewStores2026[ModeShiftAssumption],0),0),0))) -> 0 | AI27: =1-tbl_ChannelMix[[#This Row],[BoutiqueRetailShare_2026_Effective]] -> 1 | AJ27: 1 | AK27: 1 | AL27: =1-tbl_ChannelMix[[#This Row],[WholesaleRetailShare_2026]] -> 0 | AN27: United States | AO27: 15 | AP27: NA | AR27: United States | AS27: 0.323
