Workbook
Name Slicer_month: #N/A

Sheet Overview
B2: FY2026 FORECASTS MODEL
B4: This workbook plans FY2026 revenue, cost, and margin from the ground up, by country, collection, and channel, starting from actual 2025 performance and letting you adjust the assumptions to plan for the new fiscal year.
B6: Data
B7: Every gray 'Query Data' cell in this workbook was pulled via Power Query from meridian.db / SQL Server on 2026-07-20. It is correct as of that date, not live. Two source facts, fact_boutique_sales (direct/boutique channel) and fact_sell_in (wholesale shipments), are each merged with their supporting dimensions (store or wholesale customer to geography, SKU to collection, date to month/year), then appended into one consolidated actuals table, tagged by channel. That table is grouped down to Month x Channel x Collection x Country, which is the grain the Model tab works at.
B11: Workbook structure:
C12: Every editable assumption in one place: units per country, price and cost per SKU, collection mix by country, planned new store openings for 2026, and the Boutique/Wholesale and Retail/Online channel splits. Blue is input, black is formula, green is cross-sheet link.
C15: Takes 2025 actuals and 2026 Inputs assumptions and builds FY2026 at Type x Collection x Country x Month grain: a statistical shape (FORECAST.ETS, floored at zero) blended with your manual overrides, priced and costed per SKU, rolled into budgeted units, revenue, COGS, and margin.
C18: The Model's output consolidated into a full P&L, 2025 Actual vs 2026 Budget, monthly and quarterly, down to net income.
C19: Budget sliced interactively by Mode, Collection, Type, Region, and Country. Topline or detailed view without touching the Model tab.
C20: The Model's output reshaped to match fact_budget's schema exactly, splitting each row into its four channel_id values (Boutique/Wholesale x Retail/Online) using each Country/Collection's Channel Mix shares. This table is used at the end of the process to update the Database with the Official Budget for 2026

Sheet Summary
D2: OVERVIEW | N2: REGIONAL SPLIT
E3: Budget | F3: Forecast | G3: Variance | H3: Margin vs BGT | I3: Mix Budget | J3: Mix Forecast | O3: Budget | P3: Forecast | Q3: Variance | R3: Margin vs BGT | S3: Mix Budget | T3: Mix Forecast
D4: TOPLINE | E4: =IFERROR(_xlfn.XLOOKUP($D4,'Detailed Forecast'!$D:$D,'Detailed Forecast'!AB:AB,""),"") -> 1.0443122e+09 | F4: =IFERROR(_xlfn.XLOOKUP($D4,'Detailed Forecast'!$D:$D,'Detailed Forecast'!AC:AC,""),"") -> 9.609565e+08 | G4: =F4/E4-1 -> -0.079818722 | H4: =IFERROR((((_xlfn.XLOOKUP(D4,'Detailed Forecast'!D:D,'Detailed Forecast'!AC:AC)-_xlfn.XLOOKUP(D4,'Detailed Forecast'!D:D,'Detailed Forecast'!S:S))/F4)-((_xlfn.XLOOKUP(D4,'Detailed Forecast'!D:D,'Detailed Forecast'!AB:AB)-_xlfn.XLOOKUP(D4,'Detailed Forecast'!D:D,'Detailed Forecast'!R:R))/E4))*100,"") -> -0.69939207 | I4: =E4/E$4 -> 1 | J4: =F4/F$4 -> 1 | N4: EMEA | O4: =IFERROR(_xlfn.XLOOKUP($N4,'Detailed Forecast'!$D:$D,'Detailed Forecast'!AB:AB,""),"") -> 4.9486286e+08 | P4: =IFERROR(_xlfn.XLOOKUP($N4,'Detailed Forecast'!$D:$D,'Detailed Forecast'!AC:AC,""),"") -> 4.5559987e+08 | Q4: =P4/O4-1 -> -0.079341147 | R4: =IFERROR((((_xlfn.XLOOKUP(N4,'Detailed Forecast'!D:D,'Detailed Forecast'!AC:AC)-_xlfn.XLOOKUP(N4,'Detailed Forecast'!D:D,'Detailed Forecast'!S:S))/P4)-((_xlfn.XLOOKUP(N4,'Detailed Forecast'!D:D,'Detailed Forecast'!AB:AB)-_xlfn.XLOOKUP(N4,'Detailed Forecast'!D:D,'Detailed Forecast'!R:R))/O4))*100,"") -> -0.45313549 | S4: =O4/E$4 -> 0.47386488 | T4: =P4/F$4 -> 0.47411082
N5: APAC | O5: =IFERROR(_xlfn.XLOOKUP($N5,'Detailed Forecast'!$D:$D,'Detailed Forecast'!AB:AB,""),"") -> 3.097853e+08 | P5: =IFERROR(_xlfn.XLOOKUP($N5,'Detailed Forecast'!$D:$D,'Detailed Forecast'!AC:AC,""),"") -> 2.8613527e+08 | Q5: =P5/O5-1 -> -0.07634328 | R5: =IFERROR((((_xlfn.XLOOKUP(N5,'Detailed Forecast'!D:D,'Detailed Forecast'!AC:AC)-_xlfn.XLOOKUP(N5,'Detailed Forecast'!D:D,'Detailed Forecast'!S:S))/P5)-((_xlfn.XLOOKUP(N5,'Detailed Forecast'!D:D,'Detailed Forecast'!AB:AB)-_xlfn.XLOOKUP(N5,'Detailed Forecast'!D:D,'Detailed Forecast'!R:R))/O5))*100,"") -> -0.98947799 | S5: =O5/E$4 -> 0.29664052 | T5: =P5/F$4 -> 0.2977609
D6: Boutique | E6: =IFERROR(_xlfn.XLOOKUP($D6,'Detailed Forecast'!$D:$D,'Detailed Forecast'!AB:AB,""),"") -> 2.6983289e+08 | F6: =IFERROR(_xlfn.XLOOKUP($D6,'Detailed Forecast'!$D:$D,'Detailed Forecast'!AC:AC,""),"") -> 2.5378155e+08 | G6: =F6/E6-1 -> -0.059486213 | H6: =IFERROR((((_xlfn.XLOOKUP(D6,'Detailed Forecast'!D:D,'Detailed Forecast'!AC:AC)-_xlfn.XLOOKUP(D6,'Detailed Forecast'!D:D,'Detailed Forecast'!S:S))/F6)-((_xlfn.XLOOKUP(D6,'Detailed Forecast'!D:D,'Detailed Forecast'!AB:AB)-_xlfn.XLOOKUP(D6,'Detailed Forecast'!D:D,'Detailed Forecast'!R:R))/E6))*100,"") -> -0.4673047 | I6: =E6/E$4 -> 0.25838337 | J6: =F6/F$4 -> 0.26409266 | N6: NA | O6: =IFERROR(_xlfn.XLOOKUP($N6,'Detailed Forecast'!$D:$D,'Detailed Forecast'!AB:AB,""),"") -> 1.6842559e+08 | P6: =IFERROR(_xlfn.XLOOKUP($N6,'Detailed Forecast'!$D:$D,'Detailed Forecast'!AC:AC,""),"") -> 1.5592378e+08 | Q6: =P6/O6-1 -> -0.074227494 | R6: =IFERROR((((_xlfn.XLOOKUP(N6,'Detailed Forecast'!D:D,'Detailed Forecast'!AC:AC)-_xlfn.XLOOKUP(N6,'Detailed Forecast'!D:D,'Detailed Forecast'!S:S))/P6)-((_xlfn.XLOOKUP(N6,'Detailed Forecast'!D:D,'Detailed Forecast'!AB:AB)-_xlfn.XLOOKUP(N6,'Detailed Forecast'!D:D,'Detailed Forecast'!R:R))/O6))*100,"") -> -0.74113366 | S6: =O6/E$4 -> 0.16127897 | T6: =P6/F$4 -> 0.16225894
D7: Wholesale | E7: =IFERROR(_xlfn.XLOOKUP($D7,'Detailed Forecast'!$D:$D,'Detailed Forecast'!AB:AB,""),"") -> 7.7447927e+08 | F7: =IFERROR(_xlfn.XLOOKUP($D7,'Detailed Forecast'!$D:$D,'Detailed Forecast'!AC:AC,""),"") -> 7.0712027e+08 | G7: =F7/E7-1 -> -0.086973277 | H7: =IFERROR((((_xlfn.XLOOKUP(D7,'Detailed Forecast'!D:D,'Detailed Forecast'!AC:AC)-_xlfn.XLOOKUP(D7,'Detailed Forecast'!D:D,'Detailed Forecast'!S:S))/F7)-((_xlfn.XLOOKUP(D7,'Detailed Forecast'!D:D,'Detailed Forecast'!AB:AB)-_xlfn.XLOOKUP(D7,'Detailed Forecast'!D:D,'Detailed Forecast'!R:R))/E7))*100,"") -> -0.87796981 | I7: =E7/E$4 -> 0.74161663 | J7: =F7/F$4 -> 0.73585045 | N7: LATAM | O7: =IFERROR(_xlfn.XLOOKUP($N7,'Detailed Forecast'!$D:$D,'Detailed Forecast'!AB:AB,""),"") -> 71238416 | P7: =IFERROR(_xlfn.XLOOKUP($N7,'Detailed Forecast'!$D:$D,'Detailed Forecast'!AC:AC,""),"") -> 63260771 | Q7: =P7/O7-1 -> -0.11198515 | R7: =IFERROR((((_xlfn.XLOOKUP(N7,'Detailed Forecast'!D:D,'Detailed Forecast'!AC:AC)-_xlfn.XLOOKUP(N7,'Detailed Forecast'!D:D,'Detailed Forecast'!S:S))/P7)-((_xlfn.XLOOKUP(N7,'Detailed Forecast'!D:D,'Detailed Forecast'!AB:AB)-_xlfn.XLOOKUP(N7,'Detailed Forecast'!D:D,'Detailed Forecast'!R:R))/O7))*100,"") -> -1.0964388 | S7: =O7/E$4 -> 0.068215634 | T7: =P7/F$4 -> 0.065831046
Q8: =IFERROR(#REF!/O8-1,"") | S8: =IFERROR(#REF!/Q8-1,"")
D9: Online | E9: =IFERROR(_xlfn.XLOOKUP($D9,'Detailed Forecast'!$D:$D,'Detailed Forecast'!AB:AB,""),"") -> 279632185 | F9: =IFERROR(_xlfn.XLOOKUP($D9,'Detailed Forecast'!$D:$D,'Detailed Forecast'!AC:AC,""),"") -> 2.6169573e+08 | G9: =F9/E9-1 -> -0.064143013 | H9: =IFERROR((((_xlfn.XLOOKUP(D9,'Detailed Forecast'!D:D,'Detailed Forecast'!AC:AC)-_xlfn.XLOOKUP(D9,'Detailed Forecast'!D:D,'Detailed Forecast'!S:S))/F9)-((_xlfn.XLOOKUP(D9,'Detailed Forecast'!D:D,'Detailed Forecast'!AB:AB)-_xlfn.XLOOKUP(D9,'Detailed Forecast'!D:D,'Detailed Forecast'!R:R))/E9))*100,"") -> -0.66097818 | I9: =E9/E$4 -> 0.26776686 | J9: =F9/F$4 -> 0.27232839 | N9: United States | O9: =IFERROR(_xlfn.XLOOKUP($N9,'Detailed Forecast'!$D:$D,'Detailed Forecast'!AB:AB,""),"") -> 92133696 | P9: =IFERROR(_xlfn.XLOOKUP($N9,'Detailed Forecast'!$D:$D,'Detailed Forecast'!AC:AC,""),"") -> 84835011 | Q9: =P9/O9-1 -> -0.07921841 | R9: =IFERROR((((_xlfn.XLOOKUP(N9,'Detailed Forecast'!D:D,'Detailed Forecast'!AC:AC)-_xlfn.XLOOKUP(N9,'Detailed Forecast'!D:D,'Detailed Forecast'!S:S))/P9)-((_xlfn.XLOOKUP(N9,'Detailed Forecast'!D:D,'Detailed Forecast'!AB:AB)-_xlfn.XLOOKUP(N9,'Detailed Forecast'!D:D,'Detailed Forecast'!R:R))/O9))*100,"") -> -0.68471785 | S9: =O9/E$4 -> 0.088224287 | T9: =P9/F$4 -> 0.088281843
D10: Retail | E10: =IFERROR(_xlfn.XLOOKUP($D10,'Detailed Forecast'!$D:$D,'Detailed Forecast'!AB:AB,""),"") -> 7.6467998e+08 | F10: =IFERROR(_xlfn.XLOOKUP($D10,'Detailed Forecast'!$D:$D,'Detailed Forecast'!AC:AC,""),"") -> 6.9923021e+08 | G10: =F10/E10-1 -> -0.08559105 | H10: =IFERROR((((_xlfn.XLOOKUP(D10,'Detailed Forecast'!D:D,'Detailed Forecast'!AC:AC)-_xlfn.XLOOKUP(D10,'Detailed Forecast'!D:D,'Detailed Forecast'!S:S))/F10)-((_xlfn.XLOOKUP(D10,'Detailed Forecast'!D:D,'Detailed Forecast'!AB:AB)-_xlfn.XLOOKUP(D10,'Detailed Forecast'!D:D,'Detailed Forecast'!R:R))/E10))*100,"") -> -0.70274096 | I10: =E10/E$4 -> 0.73223314 | J10: =F10/F$4 -> 0.72763982 | N10: Switzerland | O10: =IFERROR(_xlfn.XLOOKUP($N10,'Detailed Forecast'!$D:$D,'Detailed Forecast'!AB:AB,""),"") -> 79478848 | P10: =IFERROR(_xlfn.XLOOKUP($N10,'Detailed Forecast'!$D:$D,'Detailed Forecast'!AC:AC,""),"") -> 73968231 | Q10: =P10/O10-1 -> -0.069334385 | R10: =IFERROR((((_xlfn.XLOOKUP(N10,'Detailed Forecast'!D:D,'Detailed Forecast'!AC:AC)-_xlfn.XLOOKUP(N10,'Detailed Forecast'!D:D,'Detailed Forecast'!S:S))/P10)-((_xlfn.XLOOKUP(N10,'Detailed Forecast'!D:D,'Detailed Forecast'!AB:AB)-_xlfn.XLOOKUP(N10,'Detailed Forecast'!D:D,'Detailed Forecast'!R:R))/O10))*100,"") -> -1.0532419 | S10: =O10/E$4 -> 0.076106409 | T10: =P10/F$4 -> 0.076973548
N11: United Kingdom | O11: =IFERROR(_xlfn.XLOOKUP($N11,'Detailed Forecast'!$D:$D,'Detailed Forecast'!AB:AB,""),"") -> 79547549 | P11: =IFERROR(_xlfn.XLOOKUP($N11,'Detailed Forecast'!$D:$D,'Detailed Forecast'!AC:AC,""),"") -> 74448962 | Q11: =P11/O11-1 -> -0.064094838 | R11: =IFERROR((((_xlfn.XLOOKUP(N11,'Detailed Forecast'!D:D,'Detailed Forecast'!AC:AC)-_xlfn.XLOOKUP(N11,'Detailed Forecast'!D:D,'Detailed Forecast'!S:S))/P11)-((_xlfn.XLOOKUP(N11,'Detailed Forecast'!D:D,'Detailed Forecast'!AB:AB)-_xlfn.XLOOKUP(N11,'Detailed Forecast'!D:D,'Detailed Forecast'!R:R))/O11))*100,"") -> 0.24504496 | S11: =O11/E$4 -> 0.076172195 | T11: =P11/F$4 -> 0.077473811
D12: Atelier | E12: =IFERROR(_xlfn.XLOOKUP($D12,'Detailed Forecast'!$D:$D,'Detailed Forecast'!AB:AB,""),"") -> 1.8825674e+08 | F12: =IFERROR(_xlfn.XLOOKUP($D12,'Detailed Forecast'!$D:$D,'Detailed Forecast'!AC:AC,""),"") -> 1.7255059e+08 | G12: =F12/E12-1 -> -0.083429429 | H12: =IFERROR((((_xlfn.XLOOKUP(D12,'Detailed Forecast'!D:D,'Detailed Forecast'!AC:AC)-_xlfn.XLOOKUP(D12,'Detailed Forecast'!D:D,'Detailed Forecast'!S:S))/F12)-((_xlfn.XLOOKUP(D12,'Detailed Forecast'!D:D,'Detailed Forecast'!AB:AB)-_xlfn.XLOOKUP(D12,'Detailed Forecast'!D:D,'Detailed Forecast'!R:R))/E12))*100,"") -> -1.0359771 | I12: =E12/E$4 -> 0.18026865 | J12: =F12/F$4 -> 0.17956129 | N12: Germany | O12: =IFERROR(_xlfn.XLOOKUP($N12,'Detailed Forecast'!$D:$D,'Detailed Forecast'!AB:AB,""),"") -> 75904894 | P12: =IFERROR(_xlfn.XLOOKUP($N12,'Detailed Forecast'!$D:$D,'Detailed Forecast'!AC:AC,""),"") -> 67001147 | Q12: =P12/O12-1 -> -0.11730136 | R12: =IFERROR((((_xlfn.XLOOKUP(N12,'Detailed Forecast'!D:D,'Detailed Forecast'!AC:AC)-_xlfn.XLOOKUP(N12,'Detailed Forecast'!D:D,'Detailed Forecast'!S:S))/P12)-((_xlfn.XLOOKUP(N12,'Detailed Forecast'!D:D,'Detailed Forecast'!AB:AB)-_xlfn.XLOOKUP(N12,'Detailed Forecast'!D:D,'Detailed Forecast'!R:R))/O12))*100,"") -> -0.53177849 | S12: =O12/E$4 -> 0.072684104 | T12: =P12/F$4 -> 0.069723392
D13: Grand Complication | E13: =IFERROR(_xlfn.XLOOKUP($D13,'Detailed Forecast'!$D:$D,'Detailed Forecast'!AB:AB,""),"") -> 1.6983548e+08 | F13: =IFERROR(_xlfn.XLOOKUP($D13,'Detailed Forecast'!$D:$D,'Detailed Forecast'!AC:AC,""),"") -> 1.6143978e+08 | G13: =F13/E13-1 -> -0.049434314 | H13: =IFERROR((((_xlfn.XLOOKUP(D13,'Detailed Forecast'!D:D,'Detailed Forecast'!AC:AC)-_xlfn.XLOOKUP(D13,'Detailed Forecast'!D:D,'Detailed Forecast'!S:S))/F13)-((_xlfn.XLOOKUP(D13,'Detailed Forecast'!D:D,'Detailed Forecast'!AB:AB)-_xlfn.XLOOKUP(D13,'Detailed Forecast'!D:D,'Detailed Forecast'!R:R))/E13))*100,"") -> -0.18612334 | I13: =E13/E$4 -> 0.16262904 | J13: =F13/F$4 -> 0.16799905 | N13: Japan | O13: =IFERROR(_xlfn.XLOOKUP($N13,'Detailed Forecast'!$D:$D,'Detailed Forecast'!AB:AB,""),"") -> 74351402 | P13: =IFERROR(_xlfn.XLOOKUP($N13,'Detailed Forecast'!$D:$D,'Detailed Forecast'!AC:AC,""),"") -> 69655670 | Q13: =P13/O13-1 -> -0.063155928 | R13: =IFERROR((((_xlfn.XLOOKUP(N13,'Detailed Forecast'!D:D,'Detailed Forecast'!AC:AC)-_xlfn.XLOOKUP(N13,'Detailed Forecast'!D:D,'Detailed Forecast'!S:S))/P13)-((_xlfn.XLOOKUP(N13,'Detailed Forecast'!D:D,'Detailed Forecast'!AB:AB)-_xlfn.XLOOKUP(N13,'Detailed Forecast'!D:D,'Detailed Forecast'!R:R))/O13))*100,"") -> -0.99668322 | S13: =O13/E$4 -> 0.07119653 | T13: =P13/F$4 -> 0.072485768
D14: Celeste | E14: =IFERROR(_xlfn.XLOOKUP($D14,'Detailed Forecast'!$D:$D,'Detailed Forecast'!AB:AB,""),"") -> 1.5011745e+08 | F14: =IFERROR(_xlfn.XLOOKUP($D14,'Detailed Forecast'!$D:$D,'Detailed Forecast'!AC:AC,""),"") -> 1.367532e+08 | G14: =F14/E14-1 -> -0.08902529 | H14: =IFERROR((((_xlfn.XLOOKUP(D14,'Detailed Forecast'!D:D,'Detailed Forecast'!AC:AC)-_xlfn.XLOOKUP(D14,'Detailed Forecast'!D:D,'Detailed Forecast'!S:S))/F14)-((_xlfn.XLOOKUP(D14,'Detailed Forecast'!D:D,'Detailed Forecast'!AB:AB)-_xlfn.XLOOKUP(D14,'Detailed Forecast'!D:D,'Detailed Forecast'!R:R))/E14))*100,"") -> -0.39945765 | I14: =E14/E$4 -> 0.14374768 | J14: =F14/F$4 -> 0.14230946 | N14: France | O14: =IFERROR(_xlfn.XLOOKUP($N14,'Detailed Forecast'!$D:$D,'Detailed Forecast'!AB:AB,""),"") -> 71167772 | P14: =IFERROR(_xlfn.XLOOKUP($N14,'Detailed Forecast'!$D:$D,'Detailed Forecast'!AC:AC,""),"") -> 65700803 | Q14: =P14/O14-1 -> -0.076818044 | R14: =IFERROR((((_xlfn.XLOOKUP(N14,'Detailed Forecast'!D:D,'Detailed Forecast'!AC:AC)-_xlfn.XLOOKUP(N14,'Detailed Forecast'!D:D,'Detailed Forecast'!S:S))/P14)-((_xlfn.XLOOKUP(N14,'Detailed Forecast'!D:D,'Detailed Forecast'!AB:AB)-_xlfn.XLOOKUP(N14,'Detailed Forecast'!D:D,'Detailed Forecast'!R:R))/O14))*100,"") -> -0.39141237 | S14: =O14/E$4 -> 0.068147988 | T14: =P14/F$4 -> 0.068370216
D15: Heritage | E15: =IFERROR(_xlfn.XLOOKUP($D15,'Detailed Forecast'!$D:$D,'Detailed Forecast'!AB:AB,""),"") -> 1.3310788e+08 | F15: =IFERROR(_xlfn.XLOOKUP($D15,'Detailed Forecast'!$D:$D,'Detailed Forecast'!AC:AC,""),"") -> 1.2663828e+08 | G15: =F15/E15-1 -> -0.048604169 | H15: =IFERROR((((_xlfn.XLOOKUP(D15,'Detailed Forecast'!D:D,'Detailed Forecast'!AC:AC)-_xlfn.XLOOKUP(D15,'Detailed Forecast'!D:D,'Detailed Forecast'!S:S))/F15)-((_xlfn.XLOOKUP(D15,'Detailed Forecast'!D:D,'Detailed Forecast'!AB:AB)-_xlfn.XLOOKUP(D15,'Detailed Forecast'!D:D,'Detailed Forecast'!R:R))/E15))*100,"") -> -0.32150116 | I15: =E15/E$4 -> 0.12745985 | J15: =F15/F$4 -> 0.13178357 | N15: China | O15: =IFERROR(_xlfn.XLOOKUP($N15,'Detailed Forecast'!$D:$D,'Detailed Forecast'!AB:AB,""),"") -> 68853049 | P15: =IFERROR(_xlfn.XLOOKUP($N15,'Detailed Forecast'!$D:$D,'Detailed Forecast'!AC:AC,""),"") -> 63340833 | Q15: =P15/O15-1 -> -0.080057692 | R15: =IFERROR((((_xlfn.XLOOKUP(N15,'Detailed Forecast'!D:D,'Detailed Forecast'!AC:AC)-_xlfn.XLOOKUP(N15,'Detailed Forecast'!D:D,'Detailed Forecast'!S:S))/P15)-((_xlfn.XLOOKUP(N15,'Detailed Forecast'!D:D,'Detailed Forecast'!AB:AB)-_xlfn.XLOOKUP(N15,'Detailed Forecast'!D:D,'Detailed Forecast'!R:R))/O15))*100,"") -> -1.1957068 | S15: =O15/E$4 -> 0.065931483 | T15: =P15/F$4 -> 0.06591436
D16: Lumina | E16: =IFERROR(_xlfn.XLOOKUP($D16,'Detailed Forecast'!$D:$D,'Detailed Forecast'!AB:AB,""),"") -> 1.0227366e+08 | F16: =IFERROR(_xlfn.XLOOKUP($D16,'Detailed Forecast'!$D:$D,'Detailed Forecast'!AC:AC,""),"") -> 91777145 | G16: =F16/E16-1 -> -0.10263166 | H16: =IFERROR((((_xlfn.XLOOKUP(D16,'Detailed Forecast'!D:D,'Detailed Forecast'!AC:AC)-_xlfn.XLOOKUP(D16,'Detailed Forecast'!D:D,'Detailed Forecast'!S:S))/F16)-((_xlfn.XLOOKUP(D16,'Detailed Forecast'!D:D,'Detailed Forecast'!AB:AB)-_xlfn.XLOOKUP(D16,'Detailed Forecast'!D:D,'Detailed Forecast'!R:R))/E16))*100,"") -> -0.87072183 | I16: =E16/E$4 -> 0.097933993 | J16: =F16/F$4 -> 0.095506035 | N16: Mexico | O16: =IFERROR(_xlfn.XLOOKUP($N16,'Detailed Forecast'!$D:$D,'Detailed Forecast'!AB:AB,""),"") -> 46863360 | P16: =IFERROR(_xlfn.XLOOKUP($N16,'Detailed Forecast'!$D:$D,'Detailed Forecast'!AC:AC,""),"") -> 46356402 | Q16: =P16/O16-1 -> -0.010817801 | R16: =IFERROR((((_xlfn.XLOOKUP(N16,'Detailed Forecast'!D:D,'Detailed Forecast'!AC:AC)-_xlfn.XLOOKUP(N16,'Detailed Forecast'!D:D,'Detailed Forecast'!S:S))/P16)-((_xlfn.XLOOKUP(N16,'Detailed Forecast'!D:D,'Detailed Forecast'!AB:AB)-_xlfn.XLOOKUP(N16,'Detailed Forecast'!D:D,'Detailed Forecast'!R:R))/O16))*100,"") -> -0.81222264 | S16: =O16/E$4 -> 0.044874858 | T16: =P16/F$4 -> 0.048239855
D17: Nautique | E17: =IFERROR(_xlfn.XLOOKUP($D17,'Detailed Forecast'!$D:$D,'Detailed Forecast'!AB:AB,""),"") -> 87971574 | F17: =IFERROR(_xlfn.XLOOKUP($D17,'Detailed Forecast'!$D:$D,'Detailed Forecast'!AC:AC,""),"") -> 77485073 | G17: =F17/E17-1 -> -0.11920329 | H17: =IFERROR((((_xlfn.XLOOKUP(D17,'Detailed Forecast'!D:D,'Detailed Forecast'!AC:AC)-_xlfn.XLOOKUP(D17,'Detailed Forecast'!D:D,'Detailed Forecast'!S:S))/F17)-((_xlfn.XLOOKUP(D17,'Detailed Forecast'!D:D,'Detailed Forecast'!AB:AB)-_xlfn.XLOOKUP(D17,'Detailed Forecast'!D:D,'Detailed Forecast'!R:R))/E17))*100,"") -> -1.2288681 | I17: =E17/E$4 -> 0.084238772 | J17: =F17/F$4 -> 0.080633278 | N17: UAE | O17: =IFERROR(_xlfn.XLOOKUP($N17,'Detailed Forecast'!$D:$D,'Detailed Forecast'!AB:AB,""),"") -> 45173303 | P17: =IFERROR(_xlfn.XLOOKUP($N17,'Detailed Forecast'!$D:$D,'Detailed Forecast'!AC:AC,""),"") -> 39326181 | Q17: =P17/O17-1 -> -0.12943755 | R17: =IFERROR((((_xlfn.XLOOKUP(N17,'Detailed Forecast'!D:D,'Detailed Forecast'!AC:AC)-_xlfn.XLOOKUP(N17,'Detailed Forecast'!D:D,'Detailed Forecast'!S:S))/P17)-((_xlfn.XLOOKUP(N17,'Detailed Forecast'!D:D,'Detailed Forecast'!AB:AB)-_xlfn.XLOOKUP(N17,'Detailed Forecast'!D:D,'Detailed Forecast'!R:R))/O17))*100,"") -> -0.34066386 | S17: =O17/E$4 -> 0.043256514 | T17: =P17/F$4 -> 0.040923998
D18: Sportivo | E18: =IFERROR(_xlfn.XLOOKUP($D18,'Detailed Forecast'!$D:$D,'Detailed Forecast'!AB:AB,""),"") -> 86284486 | F18: =IFERROR(_xlfn.XLOOKUP($D18,'Detailed Forecast'!$D:$D,'Detailed Forecast'!AC:AC,""),"") -> 78731598 | G18: =F18/E18-1 -> -0.087534721 | H18: =IFERROR((((_xlfn.XLOOKUP(D18,'Detailed Forecast'!D:D,'Detailed Forecast'!AC:AC)-_xlfn.XLOOKUP(D18,'Detailed Forecast'!D:D,'Detailed Forecast'!S:S))/F18)-((_xlfn.XLOOKUP(D18,'Detailed Forecast'!D:D,'Detailed Forecast'!AB:AB)-_xlfn.XLOOKUP(D18,'Detailed Forecast'!D:D,'Detailed Forecast'!R:R))/E18))*100,"") -> -1.1829601 | I18: =E18/E$4 -> 0.082623271 | J18: =F18/F$4 -> 0.08193045 | N18: South Korea | O18: =IFERROR(_xlfn.XLOOKUP($N18,'Detailed Forecast'!$D:$D,'Detailed Forecast'!AB:AB,""),"") -> 43348060 | P18: =IFERROR(_xlfn.XLOOKUP($N18,'Detailed Forecast'!$D:$D,'Detailed Forecast'!AC:AC,""),"") -> 42499336 | Q18: =P18/O18-1 -> -0.019579288 | R18: =IFERROR((((_xlfn.XLOOKUP(N18,'Detailed Forecast'!D:D,'Detailed Forecast'!AC:AC)-_xlfn.XLOOKUP(N18,'Detailed Forecast'!D:D,'Detailed Forecast'!S:S))/P18)-((_xlfn.XLOOKUP(N18,'Detailed Forecast'!D:D,'Detailed Forecast'!AB:AB)-_xlfn.XLOOKUP(N18,'Detailed Forecast'!D:D,'Detailed Forecast'!R:R))/O18))*100,"") -> -0.98157208 | S18: =O18/E$4 -> 0.041508719 | T18: =P18/F$4 -> 0.044226077
D19: Terra | E19: =IFERROR(_xlfn.XLOOKUP($D19,'Detailed Forecast'!$D:$D,'Detailed Forecast'!AB:AB,""),"") -> 50051302 | F19: =IFERROR(_xlfn.XLOOKUP($D19,'Detailed Forecast'!$D:$D,'Detailed Forecast'!AC:AC,""),"") -> 45788310 | G19: =F19/E19-1 -> -0.085172446 | H19: =IFERROR((((_xlfn.XLOOKUP(D19,'Detailed Forecast'!D:D,'Detailed Forecast'!AC:AC)-_xlfn.XLOOKUP(D19,'Detailed Forecast'!D:D,'Detailed Forecast'!S:S))/F19)-((_xlfn.XLOOKUP(D19,'Detailed Forecast'!D:D,'Detailed Forecast'!AB:AB)-_xlfn.XLOOKUP(D19,'Detailed Forecast'!D:D,'Detailed Forecast'!R:R))/E19))*100,"") -> -1.7754882 | I19: =E19/E$4 -> 0.04792753 | J19: =F19/F$4 -> 0.047648682 | N19: Brazil | O19: =IFERROR(_xlfn.XLOOKUP($N19,'Detailed Forecast'!$D:$D,'Detailed Forecast'!AB:AB,""),"") -> 39604826 | P19: =IFERROR(_xlfn.XLOOKUP($N19,'Detailed Forecast'!$D:$D,'Detailed Forecast'!AC:AC,""),"") -> 30673535 | Q19: =P19/O19-1 -> -0.22551016 | R19: =IFERROR((((_xlfn.XLOOKUP(N19,'Detailed Forecast'!D:D,'Detailed Forecast'!AC:AC)-_xlfn.XLOOKUP(N19,'Detailed Forecast'!D:D,'Detailed Forecast'!S:S))/P19)-((_xlfn.XLOOKUP(N19,'Detailed Forecast'!D:D,'Detailed Forecast'!AB:AB)-_xlfn.XLOOKUP(N19,'Detailed Forecast'!D:D,'Detailed Forecast'!R:R))/O19))*100,"") -> -2.5631571 | S19: =O19/E$4 -> 0.037924318 | T19: =P19/F$4 -> 0.031919796
D20: Meridian Classic | E20: =IFERROR(_xlfn.XLOOKUP($D20,'Detailed Forecast'!$D:$D,'Detailed Forecast'!AB:AB,""),"") -> 43126677 | F20: =IFERROR(_xlfn.XLOOKUP($D20,'Detailed Forecast'!$D:$D,'Detailed Forecast'!AC:AC,""),"") -> 39351989 | G20: =F20/E20-1 -> -0.087525598 | H20: =IFERROR((((_xlfn.XLOOKUP(D20,'Detailed Forecast'!D:D,'Detailed Forecast'!AC:AC)-_xlfn.XLOOKUP(D20,'Detailed Forecast'!D:D,'Detailed Forecast'!S:S))/F20)-((_xlfn.XLOOKUP(D20,'Detailed Forecast'!D:D,'Detailed Forecast'!AB:AB)-_xlfn.XLOOKUP(D20,'Detailed Forecast'!D:D,'Detailed Forecast'!R:R))/E20))*100,"") -> -0.77977085 | I20: =E20/E$4 -> 0.04129673 | J20: =F20/F$4 -> 0.040950853 | N20: Hong Kong | O20: =IFERROR(_xlfn.XLOOKUP($N20,'Detailed Forecast'!$D:$D,'Detailed Forecast'!AB:AB,""),"") -> 37213204 | P20: =IFERROR(_xlfn.XLOOKUP($N20,'Detailed Forecast'!$D:$D,'Detailed Forecast'!AC:AC,""),"") -> 31591595 | Q20: =P20/O20-1 -> -0.15106489 | R20: =IFERROR((((_xlfn.XLOOKUP(N20,'Detailed Forecast'!D:D,'Detailed Forecast'!AC:AC)-_xlfn.XLOOKUP(N20,'Detailed Forecast'!D:D,'Detailed Forecast'!S:S))/P20)-((_xlfn.XLOOKUP(N20,'Detailed Forecast'!D:D,'Detailed Forecast'!AB:AB)-_xlfn.XLOOKUP(N20,'Detailed Forecast'!D:D,'Detailed Forecast'!R:R))/O20))*100,"") -> -0.10985521 | S20: =O20/E$4 -> 0.035634177 | T20: =P20/F$4 -> 0.032875156
D21: Aventus | E21: =IFERROR(_xlfn.XLOOKUP($D21,'Detailed Forecast'!$D:$D,'Detailed Forecast'!AB:AB,""),"") -> 33286916 | F21: =IFERROR(_xlfn.XLOOKUP($D21,'Detailed Forecast'!$D:$D,'Detailed Forecast'!AC:AC,""),"") -> 30661390 | G21: =F21/E21-1 -> -0.078875604 | H21: =IFERROR((((_xlfn.XLOOKUP(D21,'Detailed Forecast'!D:D,'Detailed Forecast'!AC:AC)-_xlfn.XLOOKUP(D21,'Detailed Forecast'!D:D,'Detailed Forecast'!S:S))/F21)-((_xlfn.XLOOKUP(D21,'Detailed Forecast'!D:D,'Detailed Forecast'!AB:AB)-_xlfn.XLOOKUP(D21,'Detailed Forecast'!D:D,'Detailed Forecast'!R:R))/E21))*100,"") -> -0.81463366 | I21: =E21/E$4 -> 0.031874488 | J21: =F21/F$4 -> 0.031907157 | N21: Netherlands | O21: =IFERROR(_xlfn.XLOOKUP($N21,'Detailed Forecast'!$D:$D,'Detailed Forecast'!AB:AB,""),"") -> 35176261 | P21: =IFERROR(_xlfn.XLOOKUP($N21,'Detailed Forecast'!$D:$D,'Detailed Forecast'!AC:AC,""),"") -> 31882422 | Q21: =P21/O21-1 -> -0.093638101 | R21: =IFERROR((((_xlfn.XLOOKUP(N21,'Detailed Forecast'!D:D,'Detailed Forecast'!AC:AC)-_xlfn.XLOOKUP(N21,'Detailed Forecast'!D:D,'Detailed Forecast'!S:S))/P21)-((_xlfn.XLOOKUP(N21,'Detailed Forecast'!D:D,'Detailed Forecast'!AB:AB)-_xlfn.XLOOKUP(N21,'Detailed Forecast'!D:D,'Detailed Forecast'!R:R))/O21))*100,"") -> -0.35982831 | S21: =O21/E$4 -> 0.033683665 | T21: =P21/F$4 -> 0.0331778
N22: Italy | O22: =IFERROR(_xlfn.XLOOKUP($N22,'Detailed Forecast'!$D:$D,'Detailed Forecast'!AB:AB,""),"") -> 32110359 | P22: =IFERROR(_xlfn.XLOOKUP($N22,'Detailed Forecast'!$D:$D,'Detailed Forecast'!AC:AC,""),"") -> 30217287 | Q22: =P22/O22-1 -> -0.058955177 | R22: =IFERROR((((_xlfn.XLOOKUP(N22,'Detailed Forecast'!D:D,'Detailed Forecast'!AC:AC)-_xlfn.XLOOKUP(N22,'Detailed Forecast'!D:D,'Detailed Forecast'!S:S))/P22)-((_xlfn.XLOOKUP(N22,'Detailed Forecast'!D:D,'Detailed Forecast'!AB:AB)-_xlfn.XLOOKUP(N22,'Detailed Forecast'!D:D,'Detailed Forecast'!R:R))/O22))*100,"") -> -0.56260833 | S22: =O22/E$4 -> 0.030747855 | T22: =P22/F$4 -> 0.03144501
D23: JAN | E23: =IFERROR(_xlfn.XLOOKUP($D23,'Detailed Forecast'!$D:$D,'Detailed Forecast'!AB:AB,""),"") -> 82382445 | F23: =IFERROR(_xlfn.XLOOKUP($D23,'Detailed Forecast'!$D:$D,'Detailed Forecast'!AC:AC,""),"") -> 70958559 | G23: =F23/E23-1 -> -0.13866894 | H23: =IFERROR((((_xlfn.XLOOKUP(D23,'Detailed Forecast'!D:D,'Detailed Forecast'!AC:AC)-_xlfn.XLOOKUP(D23,'Detailed Forecast'!D:D,'Detailed Forecast'!S:S))/F23)-((_xlfn.XLOOKUP(D23,'Detailed Forecast'!D:D,'Detailed Forecast'!AB:AB)-_xlfn.XLOOKUP(D23,'Detailed Forecast'!D:D,'Detailed Forecast'!R:R))/E23))*100,"") -> -0.45473569 | I23: =E23/E$4 -> 0.0788868 | J23: =F23/F$4 -> 0.073841593 | N23: Australia | O23: =IFERROR(_xlfn.XLOOKUP($N23,'Detailed Forecast'!$D:$D,'Detailed Forecast'!AB:AB,""),"") -> 30718394 | P23: =IFERROR(_xlfn.XLOOKUP($N23,'Detailed Forecast'!$D:$D,'Detailed Forecast'!AC:AC,""),"") -> 30441847 | Q23: =P23/O23-1 -> -0.0090026601 | R23: =IFERROR((((_xlfn.XLOOKUP(N23,'Detailed Forecast'!D:D,'Detailed Forecast'!AC:AC)-_xlfn.XLOOKUP(N23,'Detailed Forecast'!D:D,'Detailed Forecast'!S:S))/P23)-((_xlfn.XLOOKUP(N23,'Detailed Forecast'!D:D,'Detailed Forecast'!AB:AB)-_xlfn.XLOOKUP(N23,'Detailed Forecast'!D:D,'Detailed Forecast'!R:R))/O23))*100,"") -> -1.3866294 | S23: =O23/E$4 -> 0.029414954 | T23: =P23/F$4 -> 0.031678694
D24: FEB | E24: =IFERROR(_xlfn.XLOOKUP($D24,'Detailed Forecast'!$D:$D,'Detailed Forecast'!AB:AB,""),"") -> 81554153 | F24: =IFERROR(_xlfn.XLOOKUP($D24,'Detailed Forecast'!$D:$D,'Detailed Forecast'!AC:AC,""),"") -> 67748869 | G24: =F24/E24-1 -> -0.16927751 | H24: =IFERROR((((_xlfn.XLOOKUP(D24,'Detailed Forecast'!D:D,'Detailed Forecast'!AC:AC)-_xlfn.XLOOKUP(D24,'Detailed Forecast'!D:D,'Detailed Forecast'!S:S))/F24)-((_xlfn.XLOOKUP(D24,'Detailed Forecast'!D:D,'Detailed Forecast'!AB:AB)-_xlfn.XLOOKUP(D24,'Detailed Forecast'!D:D,'Detailed Forecast'!R:R))/E24))*100,"") -> -0.5296515 | I24: =E24/E$4 -> 0.078093654 | J24: =F24/F$4 -> 0.070501494 | N24: Canada | O24: =IFERROR(_xlfn.XLOOKUP($N24,'Detailed Forecast'!$D:$D,'Detailed Forecast'!AB:AB,""),"") -> 29428532 | P24: =IFERROR(_xlfn.XLOOKUP($N24,'Detailed Forecast'!$D:$D,'Detailed Forecast'!AC:AC,""),"") -> 24824576 | Q24: =P24/O24-1 -> -0.15644532 | R24: =IFERROR((((_xlfn.XLOOKUP(N24,'Detailed Forecast'!D:D,'Detailed Forecast'!AC:AC)-_xlfn.XLOOKUP(N24,'Detailed Forecast'!D:D,'Detailed Forecast'!S:S))/P24)-((_xlfn.XLOOKUP(N24,'Detailed Forecast'!D:D,'Detailed Forecast'!AB:AB)-_xlfn.XLOOKUP(N24,'Detailed Forecast'!D:D,'Detailed Forecast'!R:R))/O24))*100,"") -> -0.83715245 | S24: =O24/E$4 -> 0.028179823 | T24: =P24/F$4 -> 0.025833194
D25: MAR | E25: =IFERROR(_xlfn.XLOOKUP($D25,'Detailed Forecast'!$D:$D,'Detailed Forecast'!AB:AB,""),"") -> 83697668 | F25: =IFERROR(_xlfn.XLOOKUP($D25,'Detailed Forecast'!$D:$D,'Detailed Forecast'!AC:AC,""),"") -> 84591120 | G25: =F25/E25-1 -> 0.010674752 | H25: =IFERROR((((_xlfn.XLOOKUP(D25,'Detailed Forecast'!D:D,'Detailed Forecast'!AC:AC)-_xlfn.XLOOKUP(D25,'Detailed Forecast'!D:D,'Detailed Forecast'!S:S))/F25)-((_xlfn.XLOOKUP(D25,'Detailed Forecast'!D:D,'Detailed Forecast'!AB:AB)-_xlfn.XLOOKUP(D25,'Detailed Forecast'!D:D,'Detailed Forecast'!R:R))/E25))*100,"") -> -0.44111022 | I25: =E25/E$4 -> 0.080146216 | J25: =F25/F$4 -> 0.088028043 | N25: Saudi Arabia | O25: =IFERROR(_xlfn.XLOOKUP($N25,'Detailed Forecast'!$D:$D,'Detailed Forecast'!AB:AB,""),"") -> 26604173 | P25: =IFERROR(_xlfn.XLOOKUP($N25,'Detailed Forecast'!$D:$D,'Detailed Forecast'!AC:AC,""),"") -> 26882371 | Q25: =P25/O25-1 -> 0.010456926 | R25: =IFERROR((((_xlfn.XLOOKUP(N25,'Detailed Forecast'!D:D,'Detailed Forecast'!AC:AC)-_xlfn.XLOOKUP(N25,'Detailed Forecast'!D:D,'Detailed Forecast'!S:S))/P25)-((_xlfn.XLOOKUP(N25,'Detailed Forecast'!D:D,'Detailed Forecast'!AB:AB)-_xlfn.XLOOKUP(N25,'Detailed Forecast'!D:D,'Detailed Forecast'!R:R))/O25))*100,"") -> -0.49088479 | S25: =O25/E$4 -> 0.025475307 | T25: =P25/F$4 -> 0.027974597
D26: APR | E26: =IFERROR(_xlfn.XLOOKUP($D26,'Detailed Forecast'!$D:$D,'Detailed Forecast'!AB:AB,""),"") -> 83185402 | F26: =IFERROR(_xlfn.XLOOKUP($D26,'Detailed Forecast'!$D:$D,'Detailed Forecast'!AC:AC,""),"") -> 77673877 | G26: =F26/E26-1 -> -0.06625591 | H26: =IFERROR((((_xlfn.XLOOKUP(D26,'Detailed Forecast'!D:D,'Detailed Forecast'!AC:AC)-_xlfn.XLOOKUP(D26,'Detailed Forecast'!D:D,'Detailed Forecast'!S:S))/F26)-((_xlfn.XLOOKUP(D26,'Detailed Forecast'!D:D,'Detailed Forecast'!AB:AB)-_xlfn.XLOOKUP(D26,'Detailed Forecast'!D:D,'Detailed Forecast'!R:R))/E26))*100,"") -> -0.81113205 | I26: =E26/E$4 -> 0.079655686 | J26: =F26/F$4 -> 0.080829754 | N26: Singapore | O26: =IFERROR(_xlfn.XLOOKUP($N26,'Detailed Forecast'!$D:$D,'Detailed Forecast'!AB:AB,""),"") -> 25004398 | P26: =IFERROR(_xlfn.XLOOKUP($N26,'Detailed Forecast'!$D:$D,'Detailed Forecast'!AC:AC,""),"") -> 21263202 | Q26: =P26/O26-1 -> -0.1496215 | R26: =IFERROR((((_xlfn.XLOOKUP(N26,'Detailed Forecast'!D:D,'Detailed Forecast'!AC:AC)-_xlfn.XLOOKUP(N26,'Detailed Forecast'!D:D,'Detailed Forecast'!S:S))/P26)-((_xlfn.XLOOKUP(N26,'Detailed Forecast'!D:D,'Detailed Forecast'!AB:AB)-_xlfn.XLOOKUP(N26,'Detailed Forecast'!D:D,'Detailed Forecast'!R:R))/O26))*100,"") -> -0.819001 | S26: =O26/E$4 -> 0.023943413 | T26: =P26/F$4 -> 0.022127123
D27: MAY | E27: =IFERROR(_xlfn.XLOOKUP($D27,'Detailed Forecast'!$D:$D,'Detailed Forecast'!AB:AB,""),"") -> 86045416 | F27: =IFERROR(_xlfn.XLOOKUP($D27,'Detailed Forecast'!$D:$D,'Detailed Forecast'!AC:AC,""),"") -> 82028726 | G27: =F27/E27-1 -> -0.046681048 | H27: =IFERROR((((_xlfn.XLOOKUP(D27,'Detailed Forecast'!D:D,'Detailed Forecast'!AC:AC)-_xlfn.XLOOKUP(D27,'Detailed Forecast'!D:D,'Detailed Forecast'!S:S))/F27)-((_xlfn.XLOOKUP(D27,'Detailed Forecast'!D:D,'Detailed Forecast'!AB:AB)-_xlfn.XLOOKUP(D27,'Detailed Forecast'!D:D,'Detailed Forecast'!R:R))/E27))*100,"") -> -0.99937855 | I27: =E27/E$4 -> 0.082394344 | J27: =F27/F$4 -> 0.085361539 | N27: Spain | O27: =IFERROR(_xlfn.XLOOKUP($N27,'Detailed Forecast'!$D:$D,'Detailed Forecast'!AB:AB,""),"") -> 21095213 | P27: =IFERROR(_xlfn.XLOOKUP($N27,'Detailed Forecast'!$D:$D,'Detailed Forecast'!AC:AC,""),"") -> 19524891 | Q27: =P27/O27-1 -> -0.074439735 | R27: =IFERROR((((_xlfn.XLOOKUP(N27,'Detailed Forecast'!D:D,'Detailed Forecast'!AC:AC)-_xlfn.XLOOKUP(N27,'Detailed Forecast'!D:D,'Detailed Forecast'!S:S))/P27)-((_xlfn.XLOOKUP(N27,'Detailed Forecast'!D:D,'Detailed Forecast'!AB:AB)-_xlfn.XLOOKUP(N27,'Detailed Forecast'!D:D,'Detailed Forecast'!R:R))/O27))*100,"") -> -0.499148 | S27: =O27/E$4 -> 0.020200102 | T27: =P27/F$4 -> 0.020318184
D28: JUN | E28: =IFERROR(_xlfn.XLOOKUP($D28,'Detailed Forecast'!$D:$D,'Detailed Forecast'!AB:AB,""),"") -> 86001317 | F28: =IFERROR(_xlfn.XLOOKUP($D28,'Detailed Forecast'!$D:$D,'Detailed Forecast'!AC:AC,""),"") -> 79707905 | G28: =F28/E28-1 -> -0.073178091 | H28: =IFERROR((((_xlfn.XLOOKUP(D28,'Detailed Forecast'!D:D,'Detailed Forecast'!AC:AC)-_xlfn.XLOOKUP(D28,'Detailed Forecast'!D:D,'Detailed Forecast'!S:S))/F28)-((_xlfn.XLOOKUP(D28,'Detailed Forecast'!D:D,'Detailed Forecast'!AB:AB)-_xlfn.XLOOKUP(D28,'Detailed Forecast'!D:D,'Detailed Forecast'!R:R))/E28))*100,"") -> -0.91906178 | I28: =E28/E$4 -> 0.082352117 | J28: =F28/F$4 -> 0.082946424 | N28: Peru | O28: =IFERROR(_xlfn.XLOOKUP($N28,'Detailed Forecast'!$D:$D,'Detailed Forecast'!AB:AB,""),"") -> 11872331 | P28: =IFERROR(_xlfn.XLOOKUP($N28,'Detailed Forecast'!$D:$D,'Detailed Forecast'!AC:AC,""),"") -> 10638417 | Q28: =P28/O28-1 -> -0.10393189 | R28: =IFERROR((((_xlfn.XLOOKUP(N28,'Detailed Forecast'!D:D,'Detailed Forecast'!AC:AC)-_xlfn.XLOOKUP(N28,'Detailed Forecast'!D:D,'Detailed Forecast'!S:S))/P28)-((_xlfn.XLOOKUP(N28,'Detailed Forecast'!D:D,'Detailed Forecast'!AB:AB)-_xlfn.XLOOKUP(N28,'Detailed Forecast'!D:D,'Detailed Forecast'!R:R))/O28))*100,"") -> -0.3964698 | S28: =O28/E$4 -> 0.011368565 | T28: =P28/F$4 -> 0.011070655
D29: JUL | E29: =IFERROR(_xlfn.XLOOKUP($D29,'Detailed Forecast'!$D:$D,'Detailed Forecast'!AB:AB,""),"") -> 84448323 | F29: =IFERROR(_xlfn.XLOOKUP($D29,'Detailed Forecast'!$D:$D,'Detailed Forecast'!AC:AC,""),"") -> 77704543 | G29: =F29/E29-1 -> -0.079856886 | H29: =IFERROR((((_xlfn.XLOOKUP(D29,'Detailed Forecast'!D:D,'Detailed Forecast'!AC:AC)-_xlfn.XLOOKUP(D29,'Detailed Forecast'!D:D,'Detailed Forecast'!S:S))/F29)-((_xlfn.XLOOKUP(D29,'Detailed Forecast'!D:D,'Detailed Forecast'!AB:AB)-_xlfn.XLOOKUP(D29,'Detailed Forecast'!D:D,'Detailed Forecast'!R:R))/E29))*100,"") -> -0.69798759 | I29: =E29/E$4 -> 0.08086502 | J29: =F29/F$4 -> 0.080861666 | N29: Vietnam | O29: =IFERROR(_xlfn.XLOOKUP($N29,'Detailed Forecast'!$D:$D,'Detailed Forecast'!AB:AB,""),"") -> 12312228 | P29: =IFERROR(_xlfn.XLOOKUP($N29,'Detailed Forecast'!$D:$D,'Detailed Forecast'!AC:AC,""),"") -> 10223461 | Q29: =P29/O29-1 -> -0.16964978 | R29: =IFERROR((((_xlfn.XLOOKUP(N29,'Detailed Forecast'!D:D,'Detailed Forecast'!AC:AC)-_xlfn.XLOOKUP(N29,'Detailed Forecast'!D:D,'Detailed Forecast'!S:S))/P29)-((_xlfn.XLOOKUP(N29,'Detailed Forecast'!D:D,'Detailed Forecast'!AB:AB)-_xlfn.XLOOKUP(N29,'Detailed Forecast'!D:D,'Detailed Forecast'!R:R))/O29))*100,"") -> -2.7652271 | S29: =O29/E$4 -> 0.011789797 | T29: =P29/F$4 -> 0.010638839
D30: AUG | E30: =IFERROR(_xlfn.XLOOKUP($D30,'Detailed Forecast'!$D:$D,'Detailed Forecast'!AB:AB,""),"") -> 85293961 | F30: =IFERROR(_xlfn.XLOOKUP($D30,'Detailed Forecast'!$D:$D,'Detailed Forecast'!AC:AC,""),"") -> 78482651 | G30: =F30/E30-1 -> -0.079856886 | H30: =IFERROR((((_xlfn.XLOOKUP(D30,'Detailed Forecast'!D:D,'Detailed Forecast'!AC:AC)-_xlfn.XLOOKUP(D30,'Detailed Forecast'!D:D,'Detailed Forecast'!S:S))/F30)-((_xlfn.XLOOKUP(D30,'Detailed Forecast'!D:D,'Detailed Forecast'!AB:AB)-_xlfn.XLOOKUP(D30,'Detailed Forecast'!D:D,'Detailed Forecast'!R:R))/E30))*100,"") -> -0.69939151 | I30: =E30/E$4 -> 0.081674775 | J30: =F30/F$4 -> 0.081671388 | N30: Chile | O30: =IFERROR(_xlfn.XLOOKUP($N30,'Detailed Forecast'!$D:$D,'Detailed Forecast'!AB:AB,""),"") -> 8954264.8 | P30: =IFERROR(_xlfn.XLOOKUP($N30,'Detailed Forecast'!$D:$D,'Detailed Forecast'!AC:AC,""),"") -> 10048556 | Q30: =P30/O30-1 -> 0.12220892 | R30: =IFERROR((((_xlfn.XLOOKUP(N30,'Detailed Forecast'!D:D,'Detailed Forecast'!AC:AC)-_xlfn.XLOOKUP(N30,'Detailed Forecast'!D:D,'Detailed Forecast'!S:S))/P30)-((_xlfn.XLOOKUP(N30,'Detailed Forecast'!D:D,'Detailed Forecast'!AB:AB)-_xlfn.XLOOKUP(N30,'Detailed Forecast'!D:D,'Detailed Forecast'!R:R))/O30))*100,"") -> -0.80324476 | S30: =O30/E$4 -> 0.0085743183 | T30: =P30/F$4 -> 0.010456827
D31: SEP | E31: =IFERROR(_xlfn.XLOOKUP($D31,'Detailed Forecast'!$D:$D,'Detailed Forecast'!AB:AB,""),"") -> 87377353 | F31: =IFERROR(_xlfn.XLOOKUP($D31,'Detailed Forecast'!$D:$D,'Detailed Forecast'!AC:AC,""),"") -> 80399670 | G31: =F31/E31-1 -> -0.079856886 | H31: =IFERROR((((_xlfn.XLOOKUP(D31,'Detailed Forecast'!D:D,'Detailed Forecast'!AC:AC)-_xlfn.XLOOKUP(D31,'Detailed Forecast'!D:D,'Detailed Forecast'!S:S))/F31)-((_xlfn.XLOOKUP(D31,'Detailed Forecast'!D:D,'Detailed Forecast'!AB:AB)-_xlfn.XLOOKUP(D31,'Detailed Forecast'!D:D,'Detailed Forecast'!R:R))/E31))*100,"") -> -0.69840649 | I31: =E31/E$4 -> 0.083669765 | J31: =F31/F$4 -> 0.083666295 | N31: Taiwan | O31: =IFERROR(_xlfn.XLOOKUP($N31,'Detailed Forecast'!$D:$D,'Detailed Forecast'!AB:AB,""),"") -> 8349498.7 | P31: =IFERROR(_xlfn.XLOOKUP($N31,'Detailed Forecast'!$D:$D,'Detailed Forecast'!AC:AC,""),"") -> 8144660 | Q31: =P31/O31-1 -> -0.024533053 | R31: =IFERROR((((_xlfn.XLOOKUP(N31,'Detailed Forecast'!D:D,'Detailed Forecast'!AC:AC)-_xlfn.XLOOKUP(N31,'Detailed Forecast'!D:D,'Detailed Forecast'!S:S))/P31)-((_xlfn.XLOOKUP(N31,'Detailed Forecast'!D:D,'Detailed Forecast'!AB:AB)-_xlfn.XLOOKUP(N31,'Detailed Forecast'!D:D,'Detailed Forecast'!R:R))/O31))*100,"") -> -0.15503899 | S31: =O31/E$4 -> 0.0079952135 | T31: =P31/F$4 -> 0.0084755762
D32: OCT | E32: =IFERROR(_xlfn.XLOOKUP($D32,'Detailed Forecast'!$D:$D,'Detailed Forecast'!AB:AB,""),"") -> 90973952 | F32: =IFERROR(_xlfn.XLOOKUP($D32,'Detailed Forecast'!$D:$D,'Detailed Forecast'!AC:AC,""),"") -> 83709056 | G32: =F32/E32-1 -> -0.079856886 | H32: =IFERROR((((_xlfn.XLOOKUP(D32,'Detailed Forecast'!D:D,'Detailed Forecast'!AC:AC)-_xlfn.XLOOKUP(D32,'Detailed Forecast'!D:D,'Detailed Forecast'!S:S))/F32)-((_xlfn.XLOOKUP(D32,'Detailed Forecast'!D:D,'Detailed Forecast'!AB:AB)-_xlfn.XLOOKUP(D32,'Detailed Forecast'!D:D,'Detailed Forecast'!R:R))/E32))*100,"") -> -0.69918899 | I32: =E32/E$4 -> 0.087113754 | J32: =F32/F$4 -> 0.087110141 | N32: Argentina | O32: =IFERROR(_xlfn.XLOOKUP($N32,'Detailed Forecast'!$D:$D,'Detailed Forecast'!AB:AB,""),"") -> 7486142.7 | P32: =IFERROR(_xlfn.XLOOKUP($N32,'Detailed Forecast'!$D:$D,'Detailed Forecast'!AC:AC,""),"") -> 8755372.9 | Q32: =P32/O32-1 -> 0.16954395 | R32: =IFERROR((((_xlfn.XLOOKUP(N32,'Detailed Forecast'!D:D,'Detailed Forecast'!AC:AC)-_xlfn.XLOOKUP(N32,'Detailed Forecast'!D:D,'Detailed Forecast'!S:S))/P32)-((_xlfn.XLOOKUP(N32,'Detailed Forecast'!D:D,'Detailed Forecast'!AB:AB)-_xlfn.XLOOKUP(N32,'Detailed Forecast'!D:D,'Detailed Forecast'!R:R))/O32))*100,"") -> 0.30696892 | S32: =O32/E$4 -> 0.0071684913 | T32: =P32/F$4 -> 0.0091111022
D33: NOV | E33: =IFERROR(_xlfn.XLOOKUP($D33,'Detailed Forecast'!$D:$D,'Detailed Forecast'!AB:AB,""),"") -> 96279579 | F33: =IFERROR(_xlfn.XLOOKUP($D33,'Detailed Forecast'!$D:$D,'Detailed Forecast'!AC:AC,""),"") -> 88590991 | G33: =F33/E33-1 -> -0.079856886 | H33: =IFERROR((((_xlfn.XLOOKUP(D33,'Detailed Forecast'!D:D,'Detailed Forecast'!AC:AC)-_xlfn.XLOOKUP(D33,'Detailed Forecast'!D:D,'Detailed Forecast'!S:S))/F33)-((_xlfn.XLOOKUP(D33,'Detailed Forecast'!D:D,'Detailed Forecast'!AB:AB)-_xlfn.XLOOKUP(D33,'Detailed Forecast'!D:D,'Detailed Forecast'!R:R))/E33))*100,"") -> -0.69957538 | I33: =E33/E$4 -> 0.092194252 | J33: =F33/F$4 -> 0.092190428 | N33: Greece | O33: =IFERROR(_xlfn.XLOOKUP($N33,'Detailed Forecast'!$D:$D,'Detailed Forecast'!AB:AB,""),"") -> 7250288.4 | P33: =IFERROR(_xlfn.XLOOKUP($N33,'Detailed Forecast'!$D:$D,'Detailed Forecast'!AC:AC,""),"") -> 6155204.5 | Q33: =P33/O33-1 -> -0.15104005 | R33: =IFERROR((((_xlfn.XLOOKUP(N33,'Detailed Forecast'!D:D,'Detailed Forecast'!AC:AC)-_xlfn.XLOOKUP(N33,'Detailed Forecast'!D:D,'Detailed Forecast'!S:S))/P33)-((_xlfn.XLOOKUP(N33,'Detailed Forecast'!D:D,'Detailed Forecast'!AB:AB)-_xlfn.XLOOKUP(N33,'Detailed Forecast'!D:D,'Detailed Forecast'!R:R))/O33))*100,"") -> -0.49372532 | S33: =O33/E$4 -> 0.0069426448 | T33: =P33/F$4 -> 0.0064052894
D34: DEC | E34: =IFERROR(_xlfn.XLOOKUP($D34,'Detailed Forecast'!$D:$D,'Detailed Forecast'!AB:AB,""),"") -> 97072592 | F34: =IFERROR(_xlfn.XLOOKUP($D34,'Detailed Forecast'!$D:$D,'Detailed Forecast'!AC:AC,""),"") -> 89320677 | G34: =F34/E34-1 -> -0.079856886 | H34: =IFERROR((((_xlfn.XLOOKUP(D34,'Detailed Forecast'!D:D,'Detailed Forecast'!AC:AC)-_xlfn.XLOOKUP(D34,'Detailed Forecast'!D:D,'Detailed Forecast'!S:S))/F34)-((_xlfn.XLOOKUP(D34,'Detailed Forecast'!D:D,'Detailed Forecast'!AB:AB)-_xlfn.XLOOKUP(D34,'Detailed Forecast'!D:D,'Detailed Forecast'!R:R))/E34))*100,"") -> -0.69960101 | I34: =E34/E$4 -> 0.092953616 | J34: =F34/F$4 -> 0.092949761 | N34: Belgium | O34: =IFERROR(_xlfn.XLOOKUP($N34,'Detailed Forecast'!$D:$D,'Detailed Forecast'!AB:AB,""),"") -> 7101675.1 | P34: =IFERROR(_xlfn.XLOOKUP($N34,'Detailed Forecast'!$D:$D,'Detailed Forecast'!AC:AC,""),"") -> 6195889.5 | Q34: =P34/O34-1 -> -0.12754534 | R34: =IFERROR((((_xlfn.XLOOKUP(N34,'Detailed Forecast'!D:D,'Detailed Forecast'!AC:AC)-_xlfn.XLOOKUP(N34,'Detailed Forecast'!D:D,'Detailed Forecast'!S:S))/P34)-((_xlfn.XLOOKUP(N34,'Detailed Forecast'!D:D,'Detailed Forecast'!AB:AB)-_xlfn.XLOOKUP(N34,'Detailed Forecast'!D:D,'Detailed Forecast'!R:R))/O34))*100,"") -> -0.99190417 | S34: =O34/E$4 -> 0.0068003375 | T34: =P34/F$4 -> 0.0064476275
N35: Portugal | O35: =IFERROR(_xlfn.XLOOKUP($N35,'Detailed Forecast'!$D:$D,'Detailed Forecast'!AB:AB,""),"") -> 6598666.2 | P35: =IFERROR(_xlfn.XLOOKUP($N35,'Detailed Forecast'!$D:$D,'Detailed Forecast'!AC:AC,""),"") -> 8155816.6 | Q35: =P35/O35-1 -> 0.23597957 | R35: =IFERROR((((_xlfn.XLOOKUP(N35,'Detailed Forecast'!D:D,'Detailed Forecast'!AC:AC)-_xlfn.XLOOKUP(N35,'Detailed Forecast'!D:D,'Detailed Forecast'!S:S))/P35)-((_xlfn.XLOOKUP(N35,'Detailed Forecast'!D:D,'Detailed Forecast'!AB:AB)-_xlfn.XLOOKUP(N35,'Detailed Forecast'!D:D,'Detailed Forecast'!R:R))/O35))*100,"") -> -0.63818547 | S35: =O35/E$4 -> 0.0063186722 | T35: =P35/F$4 -> 0.008487186
N36: Thailand | O36: =IFERROR(_xlfn.XLOOKUP($N36,'Detailed Forecast'!$D:$D,'Detailed Forecast'!AB:AB,""),"") -> 5800820.7 | P36: =IFERROR(_xlfn.XLOOKUP($N36,'Detailed Forecast'!$D:$D,'Detailed Forecast'!AC:AC,""),"") -> 4956554.8 | Q36: =P36/O36-1 -> -0.1455425 | R36: =IFERROR((((_xlfn.XLOOKUP(N36,'Detailed Forecast'!D:D,'Detailed Forecast'!AC:AC)-_xlfn.XLOOKUP(N36,'Detailed Forecast'!D:D,'Detailed Forecast'!S:S))/P36)-((_xlfn.XLOOKUP(N36,'Detailed Forecast'!D:D,'Detailed Forecast'!AB:AB)-_xlfn.XLOOKUP(N36,'Detailed Forecast'!D:D,'Detailed Forecast'!R:R))/O36))*100,"") -> -0.21147053 | S36: =O36/E$4 -> 0.0055546808 | T36: =P36/F$4 -> 0.0051579387
N37: Austria | O37: =IFERROR(_xlfn.XLOOKUP($N37,'Detailed Forecast'!$D:$D,'Detailed Forecast'!AB:AB,""),"") -> 3991680.5 | P37: =IFERROR(_xlfn.XLOOKUP($N37,'Detailed Forecast'!$D:$D,'Detailed Forecast'!AC:AC,""),"") -> 2467948.6 | Q37: =P37/O37-1 -> -0.38172693 | R37: =IFERROR((((_xlfn.XLOOKUP(N37,'Detailed Forecast'!D:D,'Detailed Forecast'!AC:AC)-_xlfn.XLOOKUP(N37,'Detailed Forecast'!D:D,'Detailed Forecast'!S:S))/P37)-((_xlfn.XLOOKUP(N37,'Detailed Forecast'!D:D,'Detailed Forecast'!AB:AB)-_xlfn.XLOOKUP(N37,'Detailed Forecast'!D:D,'Detailed Forecast'!R:R))/O37))*100,"") -> -0.55776235 | S37: =O37/E$4 -> 0.0038223059 | T37: =P37/F$4 -> 0.0025682209
N38: Malaysia | O38: =IFERROR(_xlfn.XLOOKUP($N38,'Detailed Forecast'!$D:$D,'Detailed Forecast'!AB:AB,""),"") -> 3834242.8 | P38: =IFERROR(_xlfn.XLOOKUP($N38,'Detailed Forecast'!$D:$D,'Detailed Forecast'!AC:AC,""),"") -> 4090033.1 | Q38: =P38/O38-1 -> 0.066712083 | R38: =IFERROR((((_xlfn.XLOOKUP(N38,'Detailed Forecast'!D:D,'Detailed Forecast'!AC:AC)-_xlfn.XLOOKUP(N38,'Detailed Forecast'!D:D,'Detailed Forecast'!S:S))/P38)-((_xlfn.XLOOKUP(N38,'Detailed Forecast'!D:D,'Detailed Forecast'!AB:AB)-_xlfn.XLOOKUP(N38,'Detailed Forecast'!D:D,'Detailed Forecast'!R:R))/O38))*100,"") -> -1.1649871 | S38: =O38/E$4 -> 0.0036715485 | T38: =P38/F$4 -> 0.0042562105
N39: Estonia | O39: =IFERROR(_xlfn.XLOOKUP($N39,'Detailed Forecast'!$D:$D,'Detailed Forecast'!AB:AB,""),"") -> 3662176.3 | P39: =IFERROR(_xlfn.XLOOKUP($N39,'Detailed Forecast'!$D:$D,'Detailed Forecast'!AC:AC,""),"") -> 3439988.7 | Q39: =P39/O39-1 -> -0.060670928 | R39: =IFERROR((((_xlfn.XLOOKUP(N39,'Detailed Forecast'!D:D,'Detailed Forecast'!AC:AC)-_xlfn.XLOOKUP(N39,'Detailed Forecast'!D:D,'Detailed Forecast'!S:S))/P39)-((_xlfn.XLOOKUP(N39,'Detailed Forecast'!D:D,'Detailed Forecast'!AB:AB)-_xlfn.XLOOKUP(N39,'Detailed Forecast'!D:D,'Detailed Forecast'!R:R))/O39))*100,"") -> -1.6801556 | S39: =O39/E$4 -> 0.0035067832 | T39: =P39/F$4 -> 0.0035797549
N40: Colombia | O40: =IFERROR(_xlfn.XLOOKUP($N40,'Detailed Forecast'!$D:$D,'Detailed Forecast'!AB:AB,""),"") -> 3320851.4 | P40: =IFERROR(_xlfn.XLOOKUP($N40,'Detailed Forecast'!$D:$D,'Detailed Forecast'!AC:AC,""),"") -> 3191324.4 | Q40: =P40/O40-1 -> -0.039004163 | R40: =IFERROR((((_xlfn.XLOOKUP(N40,'Detailed Forecast'!D:D,'Detailed Forecast'!AC:AC)-_xlfn.XLOOKUP(N40,'Detailed Forecast'!D:D,'Detailed Forecast'!S:S))/P40)-((_xlfn.XLOOKUP(N40,'Detailed Forecast'!D:D,'Detailed Forecast'!AB:AB)-_xlfn.XLOOKUP(N40,'Detailed Forecast'!D:D,'Detailed Forecast'!R:R))/O40))*100,"") -> -1.3334719 | S40: =O40/E$4 -> 0.0031799413 | T40: =P40/F$4 -> 0.0033209873

Sheet Income Statement
B2: INCOME STATEMENT
B4: Color Convention | K4: EXPENSES COEFFICIENT | M4: Represents the manual input designed for this Forecast Model, which applies to Operating, Interests and Tax Expenses as a sourch of additional variation other than the Actuals vs Budget based on Sales
B5: Blue | C5: Manual input/used in Income Statement only
B6: Black | C6: Calculated cell
B7: Green | C7: Formula that pulls from another tab/used in Income Statement only
C9: 2026 BUDGET | D9: 2026 FORECAST | E9: % | G9: EXPENSES COEFFICIENT | H9: JAN | I9: FEB | J9: MAR | K9: APR | L9: MAY | M9: JUN | N9: JUL | O9: AUG | P9: SEP | Q9: OCT | R9: NOV | S9: DEC | U9: Q1 | V9: Q2 | W9: Q3 | X9: Q4
B10: Revenue
B11: Boutique Revenue | C11: =IFERROR(_xlfn.XLOOKUP(_xlfn.TEXTBEFORE(B11," "),'Detailed Forecast'!$D$7:$D$8,'Detailed Forecast'!$AB$10:$AB$11,0),0) -> 279632185 | D11: =SUM(U11,V11,W11,X11) -> 2.5378155e+08 | E11: =D11/C11-1 -> -0.092445118 | H11: =IFERROR(_xlfn.XLOOKUP(_xlfn.CONCAT(_xlfn.TEXTBEFORE($B11," ")," - ",H$9),Model!$D$64:$D$87,Model!$AA$64:$AA$87,0),0) -> 18523464 | I11: =IFERROR(_xlfn.XLOOKUP(_xlfn.CONCAT(_xlfn.TEXTBEFORE($B11," ")," - ",I$9),Model!$D$64:$D$87,Model!$AA$64:$AA$87,0),0) -> 17268734 | J11: =IFERROR(_xlfn.XLOOKUP(_xlfn.CONCAT(_xlfn.TEXTBEFORE($B11," ")," - ",J$9),Model!$D$64:$D$87,Model!$AA$64:$AA$87,0),0) -> 22083621 | K11: =IFERROR(_xlfn.XLOOKUP(_xlfn.CONCAT(_xlfn.TEXTBEFORE($B11," ")," - ",K$9),Model!$D$64:$D$87,Model!$AA$64:$AA$87,0),0) -> 21179108 | L11: =IFERROR(_xlfn.XLOOKUP(_xlfn.CONCAT(_xlfn.TEXTBEFORE($B11," ")," - ",L$9),Model!$D$64:$D$87,Model!$AA$64:$AA$87,0),0) -> 23141212 | M11: =IFERROR(_xlfn.XLOOKUP(_xlfn.CONCAT(_xlfn.TEXTBEFORE($B11," ")," - ",M$9),Model!$D$64:$D$87,Model!$AA$64:$AA$87,0),0) -> 20251165 | N11: =IFERROR(_xlfn.XLOOKUP(_xlfn.CONCAT(_xlfn.TEXTBEFORE($B11," ")," - ",N$9),Model!$D$64:$D$87,Model!$AA$64:$AA$87,0),0) -> 20877025 | O11: =IFERROR(_xlfn.XLOOKUP(_xlfn.CONCAT(_xlfn.TEXTBEFORE($B11," ")," - ",O$9),Model!$D$64:$D$87,Model!$AA$64:$AA$87,0),0) -> 20896814 | ... S11: =IFERROR(_xlfn.XLOOKUP(_xlfn.CONCAT(_xlfn.TEXTBEFORE($B11," ")," - ",S$9),Model!$D$64:$D$87,Model!$AA$64:$AA$87,0),0) -> 23247048 | U11: =SUM(H11:J11) -> 57875818 | V11: =SUM(K11:M11) -> 64571485 | W11: =SUM(N11:P11) -> 63454008 | X11: =SUM(Q11:S11) -> 67880243
B12: Wholesale Revenue | C12: =IFERROR(_xlfn.XLOOKUP(_xlfn.TEXTBEFORE(B12," "),'Detailed Forecast'!$D$7:$D$8,'Detailed Forecast'!$AB$10:$AB$11,0),0) -> 7.6467998e+08 | D12: =SUM(U12,V12,W12,X12) -> 7.0712027e+08 | E12: =D12/C12-1 -> -0.075272936 | H12: =IFERROR(_xlfn.XLOOKUP(_xlfn.CONCAT(_xlfn.TEXTBEFORE($B12," ")," - ",H$9),Model!$D$64:$D$87,Model!$AA$64:$AA$87,0),0) -> 52435095 | I12: =IFERROR(_xlfn.XLOOKUP(_xlfn.CONCAT(_xlfn.TEXTBEFORE($B12," ")," - ",I$9),Model!$D$64:$D$87,Model!$AA$64:$AA$87,0),0) -> 50480135 | J12: =IFERROR(_xlfn.XLOOKUP(_xlfn.CONCAT(_xlfn.TEXTBEFORE($B12," ")," - ",J$9),Model!$D$64:$D$87,Model!$AA$64:$AA$87,0),0) -> 62507499 | K12: =IFERROR(_xlfn.XLOOKUP(_xlfn.CONCAT(_xlfn.TEXTBEFORE($B12," ")," - ",K$9),Model!$D$64:$D$87,Model!$AA$64:$AA$87,0),0) -> 56494769 | L12: =IFERROR(_xlfn.XLOOKUP(_xlfn.CONCAT(_xlfn.TEXTBEFORE($B12," ")," - ",L$9),Model!$D$64:$D$87,Model!$AA$64:$AA$87,0),0) -> 58887513 | M12: =IFERROR(_xlfn.XLOOKUP(_xlfn.CONCAT(_xlfn.TEXTBEFORE($B12," ")," - ",M$9),Model!$D$64:$D$87,Model!$AA$64:$AA$87,0),0) -> 59456740 | N12: =IFERROR(_xlfn.XLOOKUP(_xlfn.CONCAT(_xlfn.TEXTBEFORE($B12," ")," - ",N$9),Model!$D$64:$D$87,Model!$AA$64:$AA$87,0),0) -> 56836694 | O12: =IFERROR(_xlfn.XLOOKUP(_xlfn.CONCAT(_xlfn.TEXTBEFORE($B12," ")," - ",O$9),Model!$D$64:$D$87,Model!$AA$64:$AA$87,0),0) -> 57589573 | ... S12: =IFERROR(_xlfn.XLOOKUP(_xlfn.CONCAT(_xlfn.TEXTBEFORE($B12," ")," - ",S$9),Model!$D$64:$D$87,Model!$AA$64:$AA$87,0),0) -> 66062231 | U12: =SUM(H12:J12) -> 1.6542273e+08 | V12: =SUM(K12:M12) -> 1.7483902e+08 | W12: =SUM(N12:P12) -> 1.7315757e+08 | X12: =SUM(Q12:S12) -> 1.9370094e+08
B13: Total Net Revenue | C13: =SUM(C11:C12) -> 1.0443122e+09 | D13: =Model!AA7 -> 9.609565e+08 | E13: =D13/C13-1 -> -0.079818722 | H13: =H11+H12 -> 70958559 | I13: =I11+I12 -> 67748869 | J13: =J11+J12 -> 84591120 | K13: =K11+K12 -> 77673877 | L13: =L11+L12 -> 82028726 | M13: =M11+M12 -> 79707905 | N13: =N11+N12 -> 77713719 | O13: =O11+O12 -> 78486387 | ... S13: =S11+S12 -> 89309279 | U13: =SUM(H13:J13) -> 2.2329855e+08 | V13: =SUM(K13:M13) -> 2.3941051e+08 | W13: =SUM(N13:P13) -> 2.3661158e+08 | X13: =SUM(Q13:S13) -> 2.6158119e+08
B15: Cost of Goods Sold
B16: Boutique COGS | C16: =IFERROR(_xlfn.XLOOKUP(_xlfn.TEXTBEFORE(B16," "),'Detailed Forecast'!$D$7:$D$8,'Detailed Forecast'!$R$10:$R$11,0),0) -> 96280930 | D16: =SUM(U16,V16,W16,X16) -> 62394552 | E16: =D16/C16-1 -> -0.35195316 | H16: =IFERROR(_xlfn.XLOOKUP(_xlfn.CONCAT(_xlfn.TEXTBEFORE($B16," ")," - ",H$9),Model!$D$64:$D$87,Model!$Z$64:$Z$87,0),0) -> 4507909.5 | I16: =IFERROR(_xlfn.XLOOKUP(_xlfn.CONCAT(_xlfn.TEXTBEFORE($B16," ")," - ",I$9),Model!$D$64:$D$87,Model!$Z$64:$Z$87,0),0) -> 4216923.3 | J16: =IFERROR(_xlfn.XLOOKUP(_xlfn.CONCAT(_xlfn.TEXTBEFORE($B16," ")," - ",J$9),Model!$D$64:$D$87,Model!$Z$64:$Z$87,0),0) -> 5415470 | K16: =IFERROR(_xlfn.XLOOKUP(_xlfn.CONCAT(_xlfn.TEXTBEFORE($B16," ")," - ",K$9),Model!$D$64:$D$87,Model!$Z$64:$Z$87,0),0) -> 5221563.1 | L16: =IFERROR(_xlfn.XLOOKUP(_xlfn.CONCAT(_xlfn.TEXTBEFORE($B16," ")," - ",L$9),Model!$D$64:$D$87,Model!$Z$64:$Z$87,0),0) -> 5739560.9 | M16: =IFERROR(_xlfn.XLOOKUP(_xlfn.CONCAT(_xlfn.TEXTBEFORE($B16," ")," - ",M$9),Model!$D$64:$D$87,Model!$Z$64:$Z$87,0),0) -> 5013162.8 | N16: =IFERROR(_xlfn.XLOOKUP(_xlfn.CONCAT(_xlfn.TEXTBEFORE($B16," ")," - ",N$9),Model!$D$64:$D$87,Model!$Z$64:$Z$87,0),0) -> 5129376.6 | O16: =IFERROR(_xlfn.XLOOKUP(_xlfn.CONCAT(_xlfn.TEXTBEFORE($B16," ")," - ",O$9),Model!$D$64:$D$87,Model!$Z$64:$Z$87,0),0) -> 5133526.3 | ... S16: =IFERROR(_xlfn.XLOOKUP(_xlfn.CONCAT(_xlfn.TEXTBEFORE($B16," ")," - ",S$9),Model!$D$64:$D$87,Model!$Z$64:$Z$87,0),0) -> 5713173.6 | U16: =SUM(H16:J16) -> 14140303 | V16: =SUM(K16:M16) -> 15974287 | W16: =SUM(N16:P16) -> 15594526 | X16: =SUM(Q16:S16) -> 16685436
B17: Wholesale COGS | C17: =IFERROR(_xlfn.XLOOKUP(_xlfn.TEXTBEFORE(B17," "),'Detailed Forecast'!$D$7:$D$8,'Detailed Forecast'!$R$10:$R$11,0),0) -> 2.4957106e+08 | D17: =SUM(U17,V17,W17,X17) -> 2.6256065e+08 | E17: =D17/C17-1 -> 0.052047661 | H17: =IFERROR(_xlfn.XLOOKUP(_xlfn.CONCAT(_xlfn.TEXTBEFORE($B17," ")," - ",H$9),Model!$D$64:$D$87,Model!$Z$64:$Z$87,0),0) -> 19345015 | I17: =IFERROR(_xlfn.XLOOKUP(_xlfn.CONCAT(_xlfn.TEXTBEFORE($B17," ")," - ",I$9),Model!$D$64:$D$87,Model!$Z$64:$Z$87,0),0) -> 18585005 | J17: =IFERROR(_xlfn.XLOOKUP(_xlfn.CONCAT(_xlfn.TEXTBEFORE($B17," ")," - ",J$9),Model!$D$64:$D$87,Model!$Z$64:$Z$87,0),0) -> 23042674 | K17: =IFERROR(_xlfn.XLOOKUP(_xlfn.CONCAT(_xlfn.TEXTBEFORE($B17," ")," - ",K$9),Model!$D$64:$D$87,Model!$Z$64:$Z$87,0),0) -> 21128744 | L17: =IFERROR(_xlfn.XLOOKUP(_xlfn.CONCAT(_xlfn.TEXTBEFORE($B17," ")," - ",L$9),Model!$D$64:$D$87,Model!$Z$64:$Z$87,0),0) -> 22251307 | M17: =IFERROR(_xlfn.XLOOKUP(_xlfn.CONCAT(_xlfn.TEXTBEFORE($B17," ")," - ",M$9),Model!$D$64:$D$87,Model!$Z$64:$Z$87,0),0) -> 22172927 | N17: =IFERROR(_xlfn.XLOOKUP(_xlfn.CONCAT(_xlfn.TEXTBEFORE($B17," ")," - ",N$9),Model!$D$64:$D$87,Model!$Z$64:$Z$87,0),0) -> 21085032 | O17: =IFERROR(_xlfn.XLOOKUP(_xlfn.CONCAT(_xlfn.TEXTBEFORE($B17," ")," - ",O$9),Model!$D$64:$D$87,Model!$Z$64:$Z$87,0),0) -> 21395222 | ... S17: =IFERROR(_xlfn.XLOOKUP(_xlfn.CONCAT(_xlfn.TEXTBEFORE($B17," ")," - ",S$9),Model!$D$64:$D$87,Model!$Z$64:$Z$87,0),0) -> 24484869 | U17: =SUM(H17:J17) -> 60972693 | V17: =SUM(K17:M17) -> 65552978 | W17: =SUM(N17:P17) -> 64289067 | X17: =SUM(Q17:S17) -> 71745911
B18: Total COGS | C18: =SUM(C16:C17) -> 3.4585199e+08 | D18: =Model!Z7 -> 3.2496738e+08 | E18: =D18/C18-1 -> -0.060385977 | H18: =H16+H17 -> 23852924 | I18: =I16+I17 -> 22801928 | J18: =J16+J17 -> 28458144 | K18: =K16+K17 -> 26350307 | L18: =L16+L17 -> 27990868 | M18: =M16+M17 -> 27186090 | N18: =N16+N17 -> 26214409 | O18: =O16+O17 -> 26528748 | ... S18: =S16+S17 -> 30198042 | U18: =SUM(H18:J18) -> 75112996 | V18: =SUM(K18:M18) -> 81527265 | W18: =SUM(N18:P18) -> 79883593 | X18: =SUM(Q18:S18) -> 88431347
B20: Gross Profit
B21: Gross Profit | C21: =C13-C18 -> 6.9846017e+08 | D21: =D13-D18 -> 6.3598912e+08 | E21: =D21/C21-1 -> -0.089441109 | H21: =H13-H18 -> 47105634 | I21: =I13-I18 -> 44946941 | J21: =J13-J18 -> 56132976 | K21: =K13-K18 -> 51323570 | L21: =L13-L18 -> 54037857 | M21: =M13-M18 -> 52521815 | N21: =N13-N18 -> 51499310 | O21: =O13-O18 -> 51957639 | ... S21: =S13-S18 -> 59111237 | U21: =SUM(H21:J21) -> 1.4818555e+08 | V21: =SUM(K21:M21) -> 1.5788324e+08 | W21: =SUM(N21:P21) -> 1.5672799e+08 | X21: =SUM(Q21:S21) -> 1.7314984e+08
B22: Gross Margin % | C22: =IF(C13=0,0,C21/C13) -> 0.66882317 | D22: =IF(D13=0,0,D21/D13) -> 0.66182925 | E22: =_xlfn.CONCAT(ROUND((D22-C22)*10000,0),"pp") -> -70pp | H22: =IF(H13=0,0,H21/H13) -> 0.66384711 | I22: =IF(I13=0,0,I21/I13) -> 0.66343456 | J22: =IF(J13=0,0,J21/J13) -> 0.66358001 | K22: =IF(K13=0,0,K21/K13) -> 0.66075715 | L22: =IF(L13=0,0,L21/L13) -> 0.65876749 | M22: =IF(M13=0,0,M21/M13) -> 0.65892856 | N22: =IF(N13=0,0,N21/N13) -> 0.66267978 | O22: =IF(O13=0,0,O21/O13) -> 0.66199555 | ... S22: =IF(S13=0,0,S21/S13) -> 0.66187116 | U22: =IF(U13=0,0,U21/U13) -> 0.66362076 | V22: =IF(V13=0,0,V21/V13) -> 0.65946664 | W22: =IF(W13=0,0,W21/W13) -> 0.66238511 | X22: =IF(X13=0,0,X21/X13) -> 0.66193537
B24: Operating Expenses
B25: Ammortisation & Depreciation | C25: =-C13*0.05 -> -52215608 | D25: =-$D$13*G25 -> -48047825 | E25: =D25/C25-1 -> -0.079818722 | G25: 0.05 | H25: =-H13*0.05 -> -3547927.9 | I25: =-I13*0.05 -> -3387443.4 | J25: =-J13*0.05 -> -4229556 | K25: =-K13*0.05 -> -3883693.9 | L25: =-L13*0.05 -> -4101436.3 | M25: =-M13*0.05 -> -3985395.3 | N25: =-N13*0.05 -> -3885686 | O25: =-O13*0.05 -> -3924319.4 | ... S25: =-S13*0.05 -> -4465464 | U25: =SUM(H25:J25) -> -11164927 | V25: =SUM(K25:M25) -> -11970525 | W25: =SUM(N25:P25) -> -11830579 | X25: =SUM(Q25:S25) -> -13079059
B26: Marketing | C26: =-C13*0.1 -> -1.0443122e+08 | D26: =-$D$13*G26 -> -96095650 | E26: =D26/C26-1 -> -0.079818722 | G26: 0.1 | H26: =-H13*0.1 -> -7095855.9 | I26: =-I13*0.1 -> -6774886.9 | J26: =-J13*0.1 -> -8459112 | K26: =-K13*0.1 -> -7767387.7 | L26: =-L13*0.1 -> -8202872.6 | M26: =-M13*0.1 -> -7970790.5 | N26: =-N13*0.1 -> -7771371.9 | O26: =-O13*0.1 -> -7848638.7 | ... S26: =-S13*0.1 -> -8930927.9 | U26: =SUM(H26:J26) -> -22329855 | V26: =SUM(K26:M26) -> -23941051 | W26: =SUM(N26:P26) -> -23661158 | X26: =SUM(Q26:S26) -> -26158119
B27: General & Administrative | C27: =-C13*0.05 -> -52215608 | D27: =-$D$13*G27 -> -38438260 | E27: =D27/C27-1 -> -0.26385498 | G27: 0.04 | H27: =-H13*0.05 -> -3547927.9 | I27: =-I13*0.05 -> -3387443.4 | J27: =-J13*0.05 -> -4229556 | K27: =-K13*0.05 -> -3883693.9 | L27: =-L13*0.05 -> -4101436.3 | M27: =-M13*0.05 -> -3985395.3 | N27: =-N13*0.05 -> -3885686 | O27: =-O13*0.05 -> -3924319.4 | ... S27: =-S13*0.05 -> -4465464 | U27: =SUM(H27:J27) -> -11164927 | V27: =SUM(K27:M27) -> -11970525 | W27: =SUM(N27:P27) -> -11830579 | X27: =SUM(Q27:S27) -> -13079059
B28: Salaries & Benefits | C28: =-C13*0.2 -> -2.0886243e+08 | D28: =-$D$13*G28 -> -1.7297217e+08 | E28: =D28/C28-1 -> -0.17183685 | G28: 0.18 | H28: =-H13*0.2 -> -14191712 | I28: =-I13*0.2 -> -13549774 | J28: =-J13*0.2 -> -16918224 | K28: =-K13*0.2 -> -15534775 | L28: =-L13*0.2 -> -16405745 | M28: =-M13*0.2 -> -15941581 | N28: =-N13*0.2 -> -15542744 | O28: =-O13*0.2 -> -15697277 | ... S28: =-S13*0.2 -> -17861856 | U28: =SUM(H28:J28) -> -44659709 | V28: =SUM(K28:M28) -> -47882102 | W28: =SUM(N28:P28) -> -47322316 | X28: =SUM(Q28:S28) -> -52316238
B30: Operating Result
B31: Operating Result | C31: =C21+SUM(C25:C28) -> 2.8073531e+08 | D31: =SUM(D25:D28,D21) -> 2.8043521e+08 | E31: =D31/C31-1 -> -0.0010689503 | H31: =H21+SUM(H25:H28) -> 18722211 | I31: =I21+SUM(I25:I28) -> 17847393 | J31: =J21+SUM(J25:J28) -> 22296528 | K31: =K21+SUM(K25:K28) -> 20254019 | L31: =L21+SUM(L25:L28) -> 21226367 | M31: =M21+SUM(M25:M28) -> 20638653 | N31: =N21+SUM(N25:N28) -> 20413822 | O31: =O21+SUM(O25:O28) -> 20563084 | ... S31: =S21+SUM(S25:S28) -> 23387525 | U31: =SUM(H31:J31) -> 58866132 | V31: =SUM(K31:M31) -> 62119039 | W31: =SUM(N31:P31) -> 62083355 | X31: =SUM(Q31:S31) -> 68517365
B32: Operating Margin % | C32: =IF(C13=0,0,C31/C13) -> 0.26882317 | D32: =IF(D13=0,0,D31/D13) -> 0.29182925 | E32: =_xlfn.CONCAT(ROUND((D32-C32)*10000,0),"pp") -> 230pp | H32: =IF(H13=0,0,H31/H13) -> 0.26384711 | I32: =IF(I13=0,0,I31/I13) -> 0.26343456 | J32: =IF(J13=0,0,J31/J13) -> 0.26358001 | K32: =IF(K13=0,0,K31/K13) -> 0.26075715 | L32: =IF(L13=0,0,L31/L13) -> 0.25876749 | M32: =IF(M13=0,0,M31/M13) -> 0.25892856 | N32: =IF(N13=0,0,N31/N13) -> 0.26267978 | O32: =IF(O13=0,0,O31/O13) -> 0.26199555 | ... S32: =IF(S13=0,0,S31/S13) -> 0.26187116 | U32: =IF(U13=0,0,U31/U13) -> 0.26362076 | V32: =IF(V13=0,0,V31/V13) -> 0.25946664 | W32: =IF(W13=0,0,W31/W13) -> 0.26238511 | X32: =IF(X13=0,0,X31/X13) -> 0.26193537
B34: Interests & Taxes
B35: Net Interests Expenses | C35: =-C31*0.09 -> -25266178 | D35: =-$D$31*G35 -> -28043521 | E35: =D35/C35-1 -> 0.10992339 | G35: 0.1 | H35: =-H31*0.09 -> -1684999 | I35: =-I31*0.09 -> -1606265.4 | J35: =-J31*0.09 -> -2006687.5 | K35: =-K31*0.09 -> -1822861.7 | L35: =-L31*0.09 -> -1910373 | M35: =-M31*0.09 -> -1857478.8 | N35: =-N31*0.09 -> -1837244 | O35: =-O31*0.09 -> -1850677.6 | ... S35: =-S31*0.09 -> -2104877.2 | U35: =-U31*0.09 -> -5297951.9 | V35: =-V31*0.09 -> -5590713.5 | W35: =-W31*0.09 -> -5587502 | X35: =-X31*0.09 -> -6166562.9
B36: Corporate Tax | C36: =-(C31-C35)*0.25 -> -76500371 | D36: =-$D$31*G36 -> -70108804 | E36: =D36/C36-1 -> -0.083549496 | G36: 0.25 | H36: =-(H31-H35)*0.25 -> -5101802.4 | I36: =-(I31-I35)*0.25 -> -4863414.7 | J36: =-(J31-J35)*0.25 -> -6075803.9 | K36: =-(K31-K35)*0.25 -> -5519220.2 | L36: =-(L31-L35)*0.25 -> -5784185.1 | M36: =-(M31-M35)*0.25 -> -5624033 | N36: =-(N31-N35)*0.25 -> -5562766.6 | O36: =-(O31-O35)*0.25 -> -5603440.5 | ... S36: =-(S31-S35)*0.25 -> -6373100.5 | U36: =-(U31-U35)*0.25 -> -16041021 | V36: =-(V31-V35)*0.25 -> -16927438 | W36: =-(W31-W35)*0.25 -> -16917714 | X36: =-(X31-X35)*0.25 -> -18670982
B38: Net Income
B39: =B38 -> Net Income | C39: =C31+C35+C36 -> 1.7896876e+08 | D39: =D31+D35+D36 -> 1.8228289e+08 | E39: =D39/C39-1 -> 0.018517933 | H39: =H31+H35+H36 -> 11935409 | I39: =I31+I35+I36 -> 11377713 | J39: =J31+J35+J36 -> 14214037 | K39: =K31+K35+K36 -> 12911937 | L39: =L31+L35+L36 -> 13531809 | M39: =M31+M35+M36 -> 13157141 | N39: =N31+N35+N36 -> 13013812 | O39: =O31+O35+O36 -> 13108966 | ... S39: =S31+S35+S36 -> 14909547 | U39: =U31+U35+U36 -> 37527159 | V39: =V31+V35+V36 -> 39600888 | W39: =W31+W35+W36 -> 39578139 | X39: =X31+X35+X36 -> 43679820
B40: Net Income Margin % | C40: =IF(C13=0,0,C39/C13) -> 0.17137477 | D40: =IF(D13=0,0,D39/D13) -> 0.18968901 | E40: =_xlfn.CONCAT(ROUND((D40-C40)*10000,0),"pp") -> 183pp | H40: =IF(H13=0,0,H39/H13) -> 0.16820253 | I40: =IF(I13=0,0,I39/I13) -> 0.16793953 | J40: =IF(J13=0,0,J39/J13) -> 0.16803226 | K40: =IF(K13=0,0,K39/K13) -> 0.16623269 | L40: =IF(L13=0,0,L39/L13) -> 0.16496427 | M40: =IF(M13=0,0,M39/M13) -> 0.16506696 | N40: =IF(N13=0,0,N39/N13) -> 0.16745836 | O40: =IF(O13=0,0,O39/O13) -> 0.16702216 | ... S40: =IF(S13=0,0,S39/S13) -> 0.16694287 | U40: =IF(U13=0,0,U39/U13) -> 0.16805823 | V40: =IF(V13=0,0,V39/V13) -> 0.16540998 | W40: =IF(W13=0,0,W39/W13) -> 0.16727051 | X40: =IF(X13=0,0,X39/X13) -> 0.1669838

Sheet Detailed Forecast
D2: UNITS | P2: COGS | Z2: REVENUE
F3: LY | G3: ACTUALS | H3: BUDGET | I3: FORECAST | J3: vs LY | K3: vs ACTUALS | L3: vs BUDGET | P3: LY | Q3: ACTUALS | R3: BUDGET | S3: FORECAST | T3: vs LY | U3: vs ACTUALS | V3: vs BUDGET | Z3: LY | AA3: ACTUALS | AB3: BUDGET | AC3: FORECAST | AD3: vs LY | AE3: vs ACTUALS | AF3: vs BUDGET
